Workbook
Name Aljibe: '05.- PU Clave'!$D$21
Name Arena: '05.- PU Clave'!$D$26
Name Ayudante: '05.- PU Clave'!$D$6
Name Base100: '05.- PU Clave'!$D$24
Name Base50: '05.- PU Clave'!$D$25
Name Bolones: '05.- PU Clave'!$D$29
Name Cerámista: '05.- PU Clave'!$D$8
Name CuboDren: '05.- PU Clave'!$D$44
Name Enf: '05.- PU Clave'!$D$10
Name Excavadora: '05.- PU Clave'!$D$16
Name GasfArtef: '05.- PU Clave'!#REF!
Name GasfGrif: '05.- PU Clave'!#REF!
Name Grava: '05.- PU Clave'!$D$28
Name Gravilla: '05.- PU Clave'!$D$27
Name H: '03.- Cubicaciones'!#REF!
Name H: '03.- Cubicaciones'!#REF!
Name HormG15: '05.- PU Clave'!$D$34
Name HormG20: '05.- PU Clave'!$D$33
Name HormG25: '05.- PU Clave'!$D$32
Name HormG5: '05.- PU Clave'!$D$35
Name Jornal: '05.- PU Clave'!$D$7
Name Maestro: '05.- PU Clave'!$D$5
Name Met: '05.- PU Clave'!$D$11
Name Motoniveladora: '05.- PU Clave'!$D$18
Name Pintor: '05.- PU Clave'!$D$9
Name Retroexcavadora: '05.- PU Clave'!$D$17
Name Rodillo: '05.- PU Clave'!$D$19
Name SCAcmafor: '05.- PU Clave'!$D$39
Name SCArtElé: '05.- PU Clave'!#REF!
Name SCBulldog: '05.- PU Clave'!$D$38
Name SCHidrosembrado: '05.- PU Clave'!$D$40
Name SCHoj: '05.- PU Clave'!$D$41
Name SCPV4: '05.- PU Clave'!#REF!
Name SCSan: '05.- PU Clave'!$D$42
Name SoldadorA: '05.- PU Clave'!$D$13
Name SoldadorM: '05.- PU Clave'!$D$12
Name Tolva: '05.- PU Clave'!$D$20
Name UF: '05.- PU Clave'!$J$4

Sheet 01.- Presupuesto
H2: Fecha: | I2: 45847 | S2: Materiales | T2: =SUM(M15:M192) -> 1.8947404e+08
H3: Revisión | I3: 0 | S3: Mano de Obra | T3: =SUM(N15:N192) -> 13405164
B4: PRESUPUESTO ESTIMATIVO N° 208 | S4: Subcontratos | T4: =SUM(O15:O192) -> 1.3801322e+08
B5: OBRAS CIVILES CENTRAL LOICA | S5: Servios &Arr | T5: =SUM(P15:P192) -> 93257515
T6: =SUM(T2:T5) -> 4.3414995e+08 | V6: =I195-T6 -> 0.003372848
C7: TIPO | D7: Industrial
C8: CLIENTE | D8: Potencia Sur SpA
C9: DIRECCIÓN | D9: Avenida Providencia 329, Piso 6
C10: COMUNA | D10: Providencia, RM
B12: ITEM | C12: DESCRIPCION | F12: UNIDAD | G12: CANTIDAD | H12: P. UNITARIO | I12: P. TOTAL | M12: Materiales | N12: Mano de Obra | O12: Subcontratos | P12: Servios &Arr | Q12: Total
C14: Movimiento de Tierra | I14: =SUM(I15:I36) -> 1.7009047e+08 | Q14: =SUM(Q15:Q36) -> 1.7009047e+08
B15: 1 | C15: Desbroce | S15: =I15-Q15 -> 0
B16: 1.1 | C16: Desbroce | F16: gl | G16: ='03.- Cubicaciones'!C5 -> 1 | H16: ='1.1'!$G$4 -> 19164000 | I16: =IF(G16="","",G16*H16) -> 19164000 | M16: ='1.1'!$M$4 -> 0 | N16: ='1.1'!$N$4 -> 0 | O16: ='1.1'!$O$4 -> 0 | P16: ='1.1'!$P$4 -> 19164000 | Q16: =SUM(M16:P16) -> 19164000 | S16: =I16-Q16 -> 0
B17: 2 | C17: Demoliciones y Retiros de Escombros
B18: 2.1 | C18: Excavación, carguió sobre camión y traslado a botadero, e = variable | F18: m3 | G18: ='03.- Cubicaciones'!C7 -> 890 | H18: ='2.1'!$G$4 -> 25500 | I18: =IF(G18="","",G18*H18) -> 22695000 | M18: ='2.1'!$M$4 -> 0 | N18: ='2.1'!$N$4 -> 0 | O18: ='2.1'!$O$4 -> 0 | P18: ='2.1'!$P$4 -> 22695000 | Q18: =SUM(M18:P18) -> 22695000 | S18: =I18-Q18 -> 0
B19: 2.2 | C19: Retiro y reposición zanja para ducto malla de puesta a tierra | F19: m3 | G19: ='03.- Cubicaciones'!C8 -> 400 | H19: ='2.2'!$G$4 -> 34101.438 | I19: =IF(G19="","",G19*H19) -> 13640575 | M19: ='2.2'!$M$4 -> 10400000 | N19: ='2.2'!$N$4 -> 1153555.6 | O19: ='2.2'!$O$4 -> 0 | P19: ='2.2'!$P$4 -> 2087019.6 | Q19: =SUM(M19:P19) -> 13640575 | S19: =I19-Q19 -> 0
B20: 2.3 | C20: Formación y compactación de plataforma e= variable. Relleno e= 20cm | F20: m3 | G20: ='03.- Cubicaciones'!C9 -> 754 | H20: ='2.3'!$G$4 -> 67330.534 | I20: =IF(G20="","",G20*H20) -> 50767223 | M20: ='2.3'!$M$4 -> 42295257 | N20: ='2.3'!$N$4 -> 1961044.4 | O20: ='2.3'!$O$4 -> 0 | P20: ='2.3'!$P$4 -> 6510921.2 | Q20: =SUM(M20:P20) -> 50767223 | S20: =I20-Q20 -> 0.0062984005
B21: 2.4 | C21: Tratamiento de taludes de corte con hidrosiembra según manual de carreteras | F21: gl | G21: ='03.- Cubicaciones'!C10 -> 1 | H21: ='2.4'!$G$4 -> 42742 | I21: =IF(G21="","",G21*H21) -> 42742 | M21: ='2.4'!$M$4 -> 0 | N21: ='2.4'!$N$4 -> 0 | O21: ='2.4'!$O$4 -> 42742 | P21: ='2.4'!$P$4 -> 0 | Q21: =SUM(M21:P21) -> 42742 | S21: =I21-Q21 -> 0
B22: 3 | C22: Movimiento de Tierra Camino Acceso
B23: 3.1 | C23: Sobrexcavación para caminos interiores, carguio sobre camión y traslado | F23: m3 | G23: ='03.- Cubicaciones'!C12 -> 760 | H23: ='3.1'!$G$4 -> 25500 | I23: =IF(G23="","",G23*H23) -> 19380000 | M23: ='3.1'!$M$4 -> 0 | N23: ='3.1'!$N$4 -> 0 | O23: ='3.1'!$O$4 -> 0 | P23: ='3.1'!$P$4 -> 19380000 | Q23: =SUM(M23:P23) -> 19380000 | S23: =I23-Q23 -> 0
B24: 3.2 | C24: Suministro y colocación Base Granular CBR >100% e=26cm | F24: m3 | G24: ='03.- Cubicaciones'!C13 -> 234 | H24: ='3.2'!$G$4 -> 37444.098 | I24: =IF(G24="","",G24*H24) -> 8761918.9 | M24: ='3.2'!$M$4 -> 6692400 | N24: ='3.2'!$N$4 -> 0 | O24: ='3.2'!$O$4 -> 0 | P24: ='3.2'!$P$4 -> 2069518.9 | Q24: =SUM(M24:P24) -> 8761918.9 | S24: =I24-Q24 -> 0
B25: 3.3 | C25: Suministro y colocación Sub-Base granular CBR > 50% e=20cm | F25: m3 | G25: ='03.- Cubicaciones'!C14 -> 180 | H25: ='3.3'!$G$4 -> 35161.255 | I25: =IF(G25="","",G25*H25) -> 6329025.9 | M25: ='3.3'!$M$4 -> 4680000 | N25: ='3.3'!$N$4 -> 0 | O25: ='3.3'!$O$4 -> 0 | P25: ='3.3'!$P$4 -> 1649025.9 | Q25: =SUM(M25:P25) -> 6329025.9 | S25: =I25-Q25 -> 0
B26: 3.4 | C26: Suministro y colocación de bolones para estabilización de suelos e=30cm | F26: m3 | G26: ='03.- Cubicaciones'!C15 -> 270 | H26: ='3.4'!$G$4 -> 49700 | I26: =IF(G26="","",G26*H26) -> 13419000 | M26: ='3.4'!$M$4 -> 12987000 | N26: ='3.4'!$N$4 -> 0 | O26: ='3.4'!$O$4 -> 0 | P26: ='3.4'!$P$4 -> 432000 | Q26: =SUM(M26:P26) -> 13419000 | S26: =I26-Q26 -> 0
B27: 3.5 | C27: Suministro e Instalación de Geotextil bajo la Sub-Base | F27: m2 | G27: ='03.- Cubicaciones'!C16 -> 900 | H27: ='3.5'!$G$4 -> 1623.533 | I27: =IF(G27="","",G27*H27) -> 1461179.7 | M27: ='3.5'!$M$4 -> 1188000 | N27: ='3.5'!$N$4 -> 227649.6 | O27: ='3.5'!$O$4 -> 0 | P27: ='3.5'!$P$4 -> 45530.1 | Q27: =SUM(M27:P27) -> 1461179.7 | S27: =I27-Q27 -> 0
B28: 4 | C28: Sistema Drenajes
B29: 4.1 | C29: Suministro de materiales y construcción de zanja de infiltración, incluye cubo dren | F29: m | G29: ='03.- Cubicaciones'!C18 -> 6.3 | H29: ='4.1'!$G$4 -> 315982.17 | I29: =IF(G29="","",G29*H29) -> 1990687.6 | M29: ='4.1'!$M$4 -> 680431.52 | N29: ='4.1'!$N$4 -> 241535.93 | O29: ='4.1'!$O$4 -> 767550 | P29: ='4.1'!$P$4 -> 301170.2 | Q29: =SUM(M29:P29) -> 1990687.6 | S29: =I29-Q29 -> -0.0029256162
B30: 4.2 | C30: Suministro de materiales y construcción cámaras de filtración y decantación | F30: un | G30: ='03.- Cubicaciones'!C19 -> 1 | H30: ='4.2'!$G$4 -> 650632.39 | I30: =IF(G30="","",G30*H30) -> 650632.39 | M30: ='4.2'!$M$4 -> 424713.73 | N30: ='4.2'!$N$4 -> 144355.56 | O30: ='4.2'!$O$4 -> 37692 | P30: ='4.2'!$P$4 -> 43871.111 | Q30: =SUM(M30:P30) -> 650632.39 | S30: =I30-Q30 -> 0
B31: 5 | C31: Cierre Perimetral Exterior
B32: 5.1 | C32: Suministro e instalación cierre perimetral tipo Bulldog | F32: m | G32: ='03.- Cubicaciones'!C21 -> 50 | H32: ='5.1'!$G$4 -> 30000 | I32: =IF(G32="","",G32*H32) -> 1500000 | M32: ='5.1'!$M$4 -> 0 | N32: ='5.1'!$N$4 -> 0 | O32: ='5.1'!$O$4 -> 1500000 | P32: ='5.1'!$P$4 -> 0 | Q32: =SUM(M32:P32) -> 1500000 | S32: =I32-Q32 -> 0
B33: 5.2 | C33: Suministro e instalación cierre perimetral tipo Acmafor | F33: m | G33: ='03.- Cubicaciones'!C22 -> 280 | H33: ='5.2'!$G$4 -> 30550 | I33: =IF(G33="","",G33*H33) -> 8554000 | M33: ='5.2'!$M$4 -> 0 | N33: ='5.2'!$N$4 -> 0 | O33: ='5.2'!$O$4 -> 8554000 | P33: ='5.2'!$P$4 -> 0 | Q33: =SUM(M33:P33) -> 8554000 | S33: =I33-Q33 -> 0
B34: 5.3 | C34: Suministro e instalación portón metálico vehicular 5m | F34: un | G34: ='03.- Cubicaciones'!C23 -> 1 | H34: ='5.3'!$G$4 -> 1214017 | I34: =IF(G34="","",G34*H34) -> 1214017 | M34: ='5.3'!$M$4 -> 0 | N34: ='5.3'!$N$4 -> 0 | O34: ='5.3'!$O$4 -> 1214017 | P34: ='5.3'!$P$4 -> 0 | Q34: =SUM(M34:P34) -> 1214017 | S34: =I34-Q34 -> 0
B35: 5.4 | C35: Suministro e instalación portón metálico peatonal 1m | F35: un | G35: ='03.- Cubicaciones'!C24 -> 1 | H35: ='5.4'!$G$4 -> 520466 | I35: =IF(G35="","",G35*H35) -> 520466 | M35: ='5.4'!$M$4 -> 0 | N35: ='5.4'!$N$4 -> 0 | O35: ='5.4'!$O$4 -> 520466 | P35: ='5.4'!$P$4 -> 0 | Q35: =SUM(M35:P35) -> 520466 | S35: =I35-Q35 -> 0
I36: =IF(G36="","",G36*H36)
C37: Fundación Equipos | I37: =SUM(I38:I112) -> 53573139 | Q37: =SUM(Q38:Q112) -> 53573139
B38: 6 | C38: Fundación Grupo Generador a gas GLP, 05 unidades.
B39: 6.1 | C39: Suministro e Instalación Hormigón G25(10)20-8 | F39: m3 | G39: ='03.- Cubicaciones'!C28 -> 36.75 | H39: ='6.1'!$G$4 -> 141504.27 | I39: =IF(G39="","",G39*H39) -> 5200281.8 | M39: ='6.1'!$M$4 -> 4568100.2 | N39: ='6.1'!$N$4 -> 353276.39 | O39: ='6.1'!$O$4 -> 0 | P39: ='6.1'!$P$4 -> 278905.27 | Q39: =SUM(M39:P39) -> 5200281.8 | S39: =I39-Q39 -> 0
B40: 6.2 | C40: Suministro e instalación emplantillado hormigón G5 | F40: m3 | G40: ='03.- Cubicaciones'!C29 -> 5.25 | H40: ='6.2'!$G$4 -> 120719.81 | I40: =IF(G40="","",G40*H40) -> 633778.98 | M40: ='6.2'!$M$4 -> 573217.31 | N40: ='6.2'!$N$4 -> 50468.056 | O40: ='6.2'!$O$4 -> 0 | P40: ='6.2'!$P$4 -> 10093.613 | Q40: =SUM(M40:P40) -> 633778.98 | S40: =I40-Q40 -> 0
B41: 6.3 | C41: Suministro e Instalación relleno estructural compactado al 95% DMSC | F41: m3 | G41: ='03.- Cubicaciones'!C30 -> 199.5 | H41: ='6.3'!$G$4 -> 31578.854 | I41: =IF(G41="","",G41*H41) -> 6299981.4 | M41: ='6.3'!$M$4 -> 5187000 | N41: ='6.3'!$N$4 -> 287667.83 | O41: ='6.3'!$O$4 -> 0 | P41: ='6.3'!$P$4 -> 825313.54 | Q41: =SUM(M41:P41) -> 6299981.4 | S41: =I41-Q41 -> 0
B42: 6.4 | C42: Excavación maquinaría local y traslado a botadero, hasta 20 Km | F42: m3 | G42: ='03.- Cubicaciones'!C31 -> 246.75 | H42: ='6.4'!$G$4 -> 25500 | I42: =IF(G42="","",G42*H42) -> 6292125 | M42: ='6.4'!$M$4 -> 0 | N42: ='6.4'!$N$4 -> 0 | O42: ='6.4'!$O$4 -> 0 | P42: ='6.4'!$P$4 -> 6292125 | Q42: =SUM(M42:P42) -> 6292125 | S42: =I42-Q42 -> 0
B43: 6.5 | C43: Suministro y construcción moldajes de madera o metálicos | F43: m2 | G43: ='03.- Cubicaciones'!C32 -> 35 | H43: ='6.5'!$G$4 -> 16475.796 | I43: =IF(G43="","",G43*H43) -> 576652.86 | M43: ='6.5'!$M$4 -> 414252.86 | N43: ='6.5'!$N$4 -> 135333.35 | O43: ='6.5'!$O$4 -> 0 | P43: ='6.5'!$P$4 -> 27066.655 | Q43: =SUM(M43:P43) -> 576652.86 | S43: =I43-Q43 -> 0
...

Sheet 02.- Gastos Generales
H2: Fecha: | I2: ='01.- Presupuesto'!I2 -> 45847
H3: Revisión | I3: 0
B4: DETALLE DE GASTOS GENERALES
B5: ='01.- Presupuesto'!B5 -> OBRAS CIVILES CENTRAL LOICA
C7: TIPO | D7: Industrial
C8: CLIENTE | D8: Potencia Sur SpA
C9: DIRECCIÓN | D9: Avenida Providencia 329, Piso 6
C10: COMUNA | D10: Providencia, RM
B12: ITEM | C12: DESCRIPCION | F12: UNIDAD | G12: CANTIDAD | H12: P. UNITARIO | I12: P. TOTAL
C14: Profesionales | I14: =SUM(I15:I22) -> 51620000
B15: 1.1 | C15: Geente de Proyecto | F15: mes | G15: 3 | H15: =(6500000*1.45)/3 -> 3141666.7 | I15: =IF(G15="","",G15*H15) -> 9425000
B16: 1.2 | C16: Administrador de Obra | F16: mes | G16: 3 | H16: =3000000*1.45 -> 4350000 | I16: =IF(G16="","",G16*H16) -> 13050000
B17: 1.3 | C17: Profesional de Terreno | F17: mes | G17: 3 | H17: =2000000*1.45 -> 2900000 | I17: =IF(G17="","",G17*H17) -> 8700000
B18: 1.4 | C18: Profesional Oficina Técnica | F18: mes | G18: 3 | H18: =1500000*1.45 -> 2175000 | I18: =IF(G18="","",G18*H18) -> 6525000
B19: 1.5 | C19: Profesional Calidad | F19: mes | G19: 3 | H19: =1200000*1.45 -> 1740000 | I19: =IF(G19="","",G19*H19) -> 5220000
B20: 1.6 | C20: Asistente OT | F20: mes | G20: 3 | H20: =800000*1.45 -> 1160000 | I20: =IF(G20="","",G20*H20) -> 3480000
B21: 1.7 | C21: Profesional Prevención Riesgo | F21: mes | G21: 3 | H21: =1200000*1.45 -> 1740000 | I21: =IF(G21="","",G21*H21) -> 5220000
I22: =IF(G22="","",G22*H22)
C23: Administración y Bodega | I23: =SUM(I24:I33) -> 45892500
B24: 2.1 | C24: Jefe Administrativo | F24: mes | G24: 3 | H24: =1200000*1.45 -> 1740000 | I24: =IF(G24="","",G24*H24) -> 5220000
B25: 2.2 | C25: Jefe Bodega | F25: mes | G25: 3 | H25: =1200000*1.45 -> 1740000 | I25: =IF(G25="","",G25*H25) -> 5220000
B26: 2.3 | C26: Pañolero | F26: mes | G26: 3 | H26: =700000*1.45 -> 1015000 | I26: =IF(G26="","",G26*H26) -> 3045000
B27: 2.4 | C27: Jefe de Obra | F27: mes | G27: 3 | H27: =1600000*1.45 -> 2320000 | I27: =IF(G27="","",G27*H27) -> 6960000
B28: 2.5 | C28: Capataz OOGG | F28: mes | G28: 3 | H28: =1200000*1.45 -> 1740000 | I28: =IF(G28="","",G28*H28) -> 5220000
B29: 2.6 | C29: Capataz Patio | F29: mes | G29: 3 | H29: =1200000*1.45 -> 1740000 | I29: =IF(G29="","",G29*H29) -> 5220000
B30: 2.7 | C30: Trazador | F30: mes | G30: 3 | H30: =1000000*1.45 -> 1450000 | I30: =IF(G30="","",G30*H30) -> 4350000
B31: 2.8 | C31: Ayudante Trazador | F31: mes | G31: 3 | H31: =700000*1.45 -> 1015000 | I31: =IF(G31="","",G31*H31) -> 3045000
B32: 2.9 | C32: Porteria | F32: mes | G32: 3 | H32: =(700000*1.45)*2.5 -> 2537500 | I32: =IF(G32="","",G32*H32) -> 7612500
C34: Instalación de Faenas | I34: =SUM(I35:I46) -> 26700000
B35: 3.1 | C35: Contenedor Oficinas | F35: mes | G35: 3 | H35: =300000*3 -> 900000 | I35: =IF(G35="","",G35*H35) -> 2700000
B36: 3.2 | C36: Contenedor Baños | F36: mes | G36: 3 | H36: =350000*2 -> 700000 | I36: =IF(G36="","",G36*H36) -> 2100000
B37: 3.3 | C37: Contenedor Bodegas | F37: mes | G37: 3 | H37: =200000*2 -> 400000 | I37: =IF(G37="","",G37*H37) -> 1200000
B38: 3.4 | C38: Contenedor Casino | F38: mes | G38: 3 | H38: =200000*2 -> 400000 | I38: =IF(G38="","",G38*H38) -> 1200000
B39: 3.5 | C39: Traslado Contenedor | F39: un | G39: =9*2 -> 18 | H39: 150000 | I39: =IF(G39="","",G39*H39) -> 2700000
B40: 3.6 | C40: Señalización | F40: gl | G40: 1 | H40: 3000000 | I40: =IF(G40="","",G40*H40) -> 3000000
B41: 3.7 | C41: Instalación Radiotransmición | F41: gl | G41: 1 | H41: 1200000 | I41: =IF(G41="","",G41*H41) -> 1200000
B42: 3.8 | C42: Instalación Comunicaciones | F42: gl | G42: 1 | H42: 1200000 | I42: =IF(G42="","",G42*H42) -> 1200000
B43: 3.9 | C43: Elementos de Protección Personal y Comdiciones Seguridad | F43: mes | G43: 3 | H43: 2000000 | I43: =IF(G43="","",G43*H43) -> 6000000
B44: 3.10 | C44: Consumos luz, agua, telef, etc. | F44: mes | G44: 3 | H44: =200000*4 -> 800000 | I44: =IF(G44="","",G44*H44) -> 2400000
B45: 3.11 | C45: Alhajamiento Oficinas | F45: gl | G45: 1 | H45: 3000000 | I45: =IF(G45="","",G45*H45) -> 3000000
...

Sheet 03.- Cubicaciones
C1: CANTIDAD | D1: UNIDAD
B3: Movimiento de Tierra
A4: 1 | B4: Desbroce
A5: 1.1 | B5: Desbroce | C5: 1 | D5: gl | F5: 2442 m2
A6: 2 | B6: Demoliciones y Retiros de Escombros
A7: 2.1 | B7: Excavación, carguió sobre camión y traslado a botadero, e = variable | C7: 890 | D7: m3
A8: 2.2 | B8: Retiro y reposición zanja para ducto malla de puesta a tierra | C8: 400 | D8: m3
A9: 2.3 | B9: Formación y compactación de plataforma e= variable. Relleno e= 20cm | C9: 754 | D9: m3
A10: 2.4 | B10: Tratamiento de taludes de corte con hidrosiembra según manual de carreteras | C10: 1 | D10: gl
A11: 3 | B11: Movimiento de Tierra Camino Acceso
A12: 3.1 | B12: Sobrexcavación para caminos interiores, carguio sobre camión y traslado | C12: 760 | D12: m3
A13: 3.2 | B13: Suministro y colocación Base Granular CBR >100% e=26cm | C13: =180*5*0.26 -> 234 | D13: m3
A14: 3.3 | B14: Suministro y colocación Sub-Base granular CBR > 50% e=20cm | C14: =180*5*0.2 -> 180 | D14: m3
A15: 3.4 | B15: Suministro y colocación de bolones para estabilización de suelos e=30cm | C15: =180*5*0.3 -> 270 | D15: m3
A16: 3.5 | B16: Suministro e Instalación de Geotextil bajo la Sub-Base | C16: =180*5 -> 900 | D16: m2
A17: 4 | B17: Sistema Drenajes
A18: 4.1 | B18: Suministro de materiales y construcción de zanja de infiltración, incluye cubo dren | C18: 6.3 | D18: m
A19: 4.2 | B19: Suministro de materiales y construcción cámaras de filtración y decantación | C19: 1 | D19: un
A20: 5 | B20: Cierre Perimetral Exterior
A21: 5.1 | B21: Suministro e instalación cierre perimetral tipo Bulldog | C21: 50 | D21: m
A22: 5.2 | B22: Suministro e instalación cierre perimetral tipo Acmafor | C22: 280 | D22: m | F22: =2.5*110+1+2.1+1.8 -> 279.9
A23: 5.3 | B23: Suministro e instalación portón metálico vehicular 5m | C23: 1 | D23: un
A24: 5.4 | B24: Suministro e instalación portón metálico peatonal 1m | C24: 1 | D24: un
B26: Fundación Equipos
A27: 6 | B27: Fundación Grupo Generador a gas GLP, 05 unidades.
A28: 6.1 | B28: Suministro e Instalación Hormigón G25(10)20-8 | C28: =F28*5 -> 36.75 | D28: m3 | F28: =7*3*0.35 -> 7.35 | I28: F1 | J28: 1 | K28: =J28*M28 -> 392.757 | M28: =SUM(M30:M32) -> 392.757
A29: 6.2 | B29: Suministro e instalación emplantillado hormigón G5 | C29: =F29*5 -> 5.25 | D29: m3 | F29: =7*3*0.05 -> 1.05 | I29: Cant | J29: diámetro | K29: L | L29: Kg/ml | M29: Kg
A30: 6.3 | B30: Suministro e Instalación relleno estructural compactado al 95% DMSC | C30: =F30*5 -> 199.5 | D30: m3 | F30: =7*3*1.9 -> 39.9 | I30: 30 | J30: 12 | K30: 7.15 | L30: 0.89 | M30: =I30*K30*L30 -> 190.905
A31: 6.4 | B31: Excavación maquinaría local y traslado a botadero, hasta 20 Km | C31: =F31*5 -> 246.75 | D31: m3 | F31: =7*3*(1.9+0.1+0.35) -> 49.35 | I31: =36*2 -> 72 | J31: 12 | K31: 3.15 | L31: 0.89 | M31: =I31*K31*L31 -> 201.852
A32: 6.5 | B32: Suministro y construcción moldajes de madera o metálicos | C32: =F32*5 -> 35 | D32: m2 | F32: =0.35*(7*2+3*2) -> 7
A33: 6.6 | B33: Suministro e instalación armadura A630-420H, diámetro 12mm | C33: =F33*5 -> 1963.785 | D33: kg | F33: =K28 -> 392.757
A34: 6.7 | B34: Suministro e instalación de pernos de anclaje químico | C34: 280 | D34: un
A35: 7 | B35: Fundación Transformador 2,0 MVA, 05 unidades
A36: 7.1 | B36: Suministro e Instalación Hormigón G20(10)20-8 | C36: =F36*5 -> 20 | D36: m3 | F36: 4
A37: 7.2 | B37: Suministro e instalación emplantillado hormigón G5 | C37: =F37*5 -> 2.5 | D37: m3 | F37: 0.5
A38: 7.3 | B38: Suministro e Instalación relleno estructural compactado al 95% DMSC | C38: =F38*5 -> 24.3775 | D38: m3 | F38: =3.1*3.1*0.7-2.3*2.3*0.35 -> 4.8755
A39: 7.4 | B39: Excavación maquinaría local y traslado a botadero, hasta 20 Km | C39: =F39*5 -> 48.05 | D39: m3 | F39: =3.1*3.1*(0.35+0.65) -> 9.61
A40: 7.5 | B40: Suministro y construcción moldajes de madera o metálicos | C40: =F40*5 -> 95 | D40: m2 | F40: 19
A41: 7.6 | B41: Suministro e instalación armadura A630-420H, diámetro 12mm | C41: =F41*5 -> 600 | D41: kg | F41: 120
A42: 7.7 | B42: Suministro e instalación de pernos de anclaje químico | C42: =F42*5 -> 20 | D42: un | F42: 4
...

Sheet 04.- CC Cubicaciones
B2: Movimiento de Tierra | D2: GECOT | E2: ITEMIZADO | F2: DELTA
A3: 1 | B3: Desbroce
A4: 1.1 | B4: Desbroce | C4: gl | D4: ='03.- Cubicaciones'!C5 -> 1 | E4: 1 | F4: =E4-D4 -> 0 | G4: =F4/E4 -> 0
A5: 2 | B5: Demoliciones y Retiros de Escombros
A6: 2.1 | B6: Excavación, carguió sobre camión y traslado a botadero, e = variable | C6: m3 | D6: ='03.- Cubicaciones'!C7 -> 890 | E6: =640+250 -> 890 | F6: =E6-D6 -> 0 | G6: =F6/E6 -> 0
A7: 2.2 | B7: Retiro y reposición zanja para ducto malla de puesta a tierra | C7: m3 | D7: ='03.- Cubicaciones'!C8 -> 400 | E7: 400 | F7: =E7-D7 -> 0 | G7: =F7/E7 -> 0
A8: 2.3 | B8: Formación y compactación de plataforma e= variable. Relleno e= 20cm | C8: m3 | D8: ='03.- Cubicaciones'!C9 -> 754 | E8: =(768-870*0.4)*1.2+250 -> 754 | F8: =E8-D8 -> 0 | G8: =F8/E8 -> 0
A9: 2.4 | B9: Tratamiento de taludes de corte con hidrosiembra según manual de carreteras | C9: gl | D9: ='03.- Cubicaciones'!C10 -> 1 | E9: 1 | F9: =E9-D9 -> 0 | G9: =F9/E9 -> 0
A10: 3 | B10: Movimiento de Tierra Camino Acceso
A11: 3.1 | B11: Sobrexcavación para caminos interiores, carguio sobre camión y traslado | C11: m3 | D11: ='03.- Cubicaciones'!C12 -> 760 | E11: =860*0.8*1.1 -> 756.8 | F11: =E11-D11 -> -3.2 | G11: =F11/E11 -> -0.0042283298
A12: 3.2 | B12: Suministro y colocación Base Granular CBR >100% e=26cm | C12: m3 | D12: ='03.- Cubicaciones'!C13 -> 234 | E12: 240 | F12: =E12-D12 -> 6 | G12: =F12/E12 -> 0.025
A13: 3.3 | B13: Suministro y colocación Sub-Base granular CBR > 50% e=20cm | C13: m3 | D13: ='03.- Cubicaciones'!C14 -> 180 | E13: 180 | F13: =E13-D13 -> 0 | G13: =F13/E13 -> 0
A14: 3.4 | B14: Suministro y colocación de bolones para estabilización de suelos e=30cm | C14: m3 | D14: ='03.- Cubicaciones'!C15 -> 270 | E14: 270 | F14: =E14-D14 -> 0 | G14: =F14/E14 -> 0
A15: 3.5 | B15: Suministro e Instalación de Geotextil bajo la Sub-Base | C15: m2 | D15: ='03.- Cubicaciones'!C16 -> 900 | E15: =860*1.2 -> 1032 | F15: =E15-D15 -> 132 | G15: =F15/E15 -> 0.12790698
A16: 4 | B16: Sistema Drenajes
A17: 4.1 | B17: Suministro de materiales y construcción de zanja de infiltración, incluye cubo dren | C17: m | D17: ='03.- Cubicaciones'!C18 -> 6.3 | E17: 6.3 | F17: =E17-D17 -> 0 | G17: =F17/E17 -> 0
A18: 4.2 | B18: Suministro de materiales y construcción cámaras de filtración y decantación | C18: un | D18: ='03.- Cubicaciones'!C19 -> 1 | E18: 1 | F18: =E18-D18 -> 0 | G18: =F18/E18 -> 0
A19: 5 | B19: Cierre Perimetral Exterior
A20: 5.1 | B20: Suministro e instalación cierre perimetral tipo Bulldog | C20: m | D20: ='03.- Cubicaciones'!C21 -> 50 | E20: 50 | F20: =E20-D20 -> 0 | G20: =F20/E20 -> 0
A21: 5.2 | B21: Suministro e instalación cierre perimetral tipo Acmafor | C21: m | D21: ='03.- Cubicaciones'!C22 -> 280 | E21: 362 | F21: =E21-D21 -> 82 | G21: =F21/E21 -> 0.22651934
A22: 5.3 | B22: Suministro e instalación portón metálico vehicular 5m | C22: un | D22: ='03.- Cubicaciones'!C23 -> 1 | E22: 1 | F22: =E22-D22 -> 0 | G22: =F22/E22 -> 0
A23: 5.4 | B23: Suministro e instalación portón metálico peatonal 1m | C23: un | D23: ='03.- Cubicaciones'!C24 -> 1 | E23: 1 | F23: =E23-D23 -> 0 | G23: =F23/E23 -> 0
B25: Fundación Equipos
A26: 6 | B26: Fundación Grupo Generador a gas GLP, 05 unidades.
A27: 6.1 | B27: Suministro e Instalación Hormigón G25(10)20-8 | C27: m3 | D27: ='03.- Cubicaciones'!C28 -> 36.75 | E27: =8*5 -> 40 | F27: =E27-D27 -> 3.25 | G27: =F27/E27 -> 0.08125
A28: 6.2 | B28: Suministro e instalación emplantillado hormigón G5 | C28: m3 | D28: ='03.- Cubicaciones'!C29 -> 5.25 | E28: =2.1*5 -> 10.5 | F28: =E28-D28 -> 5.25 | G28: =F28/E28 -> 0.5
A29: 6.3 | B29: Suministro e Instalación relleno estructural compactado al 95% DMSC | C29: m3 | D29: ='03.- Cubicaciones'!C30 -> 199.5 | E29: =24.15*5 -> 120.75 | F29: =E29-D29 -> -78.75 | G29: =F29/E29 -> -0.65217391
A30: 6.4 | B30: Excavación maquinaría local y traslado a botadero, hasta 20 Km | C30: m3 | D30: ='03.- Cubicaciones'!C31 -> 246.75 | E30: =+(23+2.1+8)*5 -> 165.5 | F30: =E30-D30 -> -81.25 | G30: =F30/E30 -> -0.49093656
A31: 6.5 | B31: Suministro y construcción moldajes de madera o metálicos | C31: m2 | D31: ='03.- Cubicaciones'!C32 -> 35 | E31: =8*5 -> 40 | F31: =E31-D31 -> 5 | G31: =F31/E31 -> 0.125
A32: 6.6 | B32: Suministro e instalación armadura A630-420H, diámetro 12mm | C32: kg | D32: ='03.- Cubicaciones'!C33 -> 1963.785 | E32: =452*5*1.1 -> 2486 | F32: =E32-D32 -> 522.215 | G32: =F32/E32 -> 0.21006235
A33: 6.7 | B33: Suministro e instalación de pernos de anclaje químico | C33: un | D33: ='03.- Cubicaciones'!C34 -> 280 | E33: =56*5 -> 280 | F33: =E33-D33 -> 0 | G33: =F33/E33 -> 0
A34: 7 | B34: Fundación Transformador 2,0 MVA, 05 unidades
A35: 7.1 | B35: Suministro e Instalación Hormigón G20(10)20-8 | C35: m3 | D35: ='03.- Cubicaciones'!C36 -> 20 | E35: =4*5 -> 20 | F35: =E35-D35 -> 0 | G35: =F35/E35 -> 0
A36: 7.2 | B36: Suministro e instalación emplantillado hormigón G5 | C36: m3 | D36: ='03.- Cubicaciones'!C37 -> 2.5 | E36: =0.5*5 -> 2.5 | F36: =E36-D36 -> 0 | G36: =F36/E36 -> 0
A37: 7.3 | B37: Suministro e Instalación relleno estructural compactado al 95% DMSC | C37: m3 | D37: ='03.- Cubicaciones'!C38 -> 24.3775 | E37: =4*2.1 -> 8.4 | F37: =E37-D37 -> -15.9775 | G37: =F37/E37 -> -1.9020833
A38: 7.4 | B38: Excavación maquinaría local y traslado a botadero, hasta 20 Km | C38: m3 | D38: ='03.- Cubicaciones'!C39 -> 48.05 | E38: =4.5*5 -> 22.5 | F38: =E38-D38 -> -25.55 | G38: =F38/E38 -> -1.1355556
A39: 7.5 | B39: Suministro y construcción moldajes de madera o metálicos | C39: m2 | D39: ='03.- Cubicaciones'!C40 -> 95 | E39: =19*5 -> 95 | F39: =E39-D39 -> 0 | G39: =F39/E39 -> 0
A40: 7.6 | B40: Suministro e instalación armadura A630-420H, diámetro 12mm | C40: kg | D40: ='03.- Cubicaciones'!C41 -> 600 | E40: =12*5 -> 60 | F40: =E40-D40 -> -540 | G40: =F40/E40 -> -9
A41: 7.7 | B41: Suministro e instalación de pernos de anclaje químico | C41: un | D41: ='03.- Cubicaciones'!C42 -> 20 | E41: =4*5 -> 20 | F41: =E41-D41 -> 0 | G41: =F41/E41 -> 0
A42: 7.8 | B42: Suministro e instalación enfierradura malla acma C-188 | C42: kg | D42: ='03.- Cubicaciones'!C43 -> 180 | E42: =36*5 -> 180 | F42: =E42-D42 -> 0 | G42: =F42/E42 -> 0
...

Sheet 05.- PU Clave
C4: Sueldos | D4: HH | E4: Sueldo L. | F4: Sueldo B. | I4: UF | J4: 39267
C5: Maestro | D5: =F5/180 -> 7250 | E5: 900000 | F5: =E5*1.45 -> 1305000
C6: Ayudante | D6: =F6/180 -> 5638.8889 | E6: 700000 | F6: =E6*1.45 -> 1015000
C7: Jornal | D7: =F7/180 -> 5397.2222 | E7: 670000 | F7: =E7*1.45 -> 971500
C8: Cerámista | D8: =F8/180 -> 11680.556 | E8: 1450000 | F8: =E8*1.45 -> 2102500
C9: Pintor | D9: =F9/180 -> 8055.5556 | E9: 1000000 | F9: =E9*1.45 -> 1450000
C10: SC Enfierrador | D10: 600
C11: SC Perfilería Metálica | D11: 1500
C12: Maestro Soldador | D12: =F12/180 -> 8055.5556 | E12: 1000000 | F12: =E12*1.45 -> 1450000
C13: Ayudante Soldador | D13: =F13/180 -> 7250 | E13: 900000 | F13: =E13*1.45 -> 1305000
C15: Maquinaría | D15: HM
C16: Excavadora | D16: 50000
C17: Retroexcavadora | D17: 32000
C18: Motoniveladora | D18: 62000
C19: Rodillo | D19: 42000
C20: Camión Tolva | D20: 38000
C21: Camión Aljibe | D21: 32000
C23: Aridos | D23: PU
C24: Base Granular CBR >100% | D24: 22000
C25: Base Granular CBR >50% | D25: 20000
C26: Arena | D26: 24000
C27: Gravilla | D27: 26000
C28: Grava Limpia | D28: 28000
C29: Bolones | D29: 37000
C31: Hormigón | D31: M3
C32: Hormigón G25(10)20-8 | D32: =2.85*UF -> 111910.95
C33: Hormigón G20(10)20-8 | D33: =2.76*UF -> 108376.92
C34: Hormigón G15(10)20-8 | D34: =2.67*UF -> 104842.89
C35: Hormigón G5 | D35: =2.5*UF -> 98167.5
C37: Subcontratos | D37: Ml
C38: Subcontrato Sum e Inst Bulldog | D38: 30000
C39: Subcontrato Sum e Inst Acmafor | D39: 30550
C40: Subcontrato Hidrosembrado | D40: 42742
C41: Subcontrato Sum e Instalación Hojalatería | D41: 16500
C42: Subcontrato Instalación Sanitaria | D42: 17000
C44: Cubo Dren Insytec | D44: 11390 | E44: un

Sheet 1.1
B1: 02.- Presupuesto'!A1
B3: Código | C3: Recurso | D3: Unidad | E3: Descripción | F3: Cantidad | G3: Precio Unitario | H3: Total | M3: Mat | N3: MO | O3: SC | P3: Arr
B4: 1.1 | C4: Partida | D4: ='01.- Presupuesto'!F16 -> gl | E4: ='01.- Presupuesto'!C16 -> Desbroce | F4: ='01.- Presupuesto'!G16 -> 1 | G4: =G9 -> 19164000 | H4: =H9 -> 19164000 | J4: Cantidad | K4: Costo | M4: =SUMIF(C5:C21,"Material",K5:K21) -> 0 | N4: =SUMIF(C5:C21,"Mano de Obra",K5:K21) -> 0 | O4: =SUMIF(C5:C21,"Subcontrato",K5:K21) -> 0 | P4: =SUMIF(C5:C21,"Ser&Arr",K5:K21) -> 19164000 | Q4: =SUM(M4:P4) -> 19164000
C5: Ser&Arr | D5: hm | E5: Motoniveladora | F5: =ROUNDUP(1/20*2442*0.3,0) -> 37 | G5: =Motoniveladora -> 62000 | H5: =ROUND(F5*G5,3) -> 2294000 | J5: =F5*$F$4 -> 37 | K5: =H5*$F$4 -> 2294000
C6: Ser&Arr | D6: hm | E6: Retroexcavadora | F6: =ROUNDUP(1/20*2442*0.3,0) -> 37 | G6: =Retroexcavadora -> 32000 | H6: =ROUND(F6*G6,3) -> 1184000 | J6: =F6*$F$4 -> 37 | K6: =H6*$F$4 -> 1184000
C7: Ser&Arr | D7: hm | E7: Camión Tolva | F7: =ROUNDUP(1/20*2442*0.3,0) -> 37 | G7: =Tolva -> 38000 | H7: =ROUND(F7*G7,3) -> 1406000 | J7: =F7*$F$4 -> 37 | K7: =H7*$F$4 -> 1406000
C8: Ser&Arr | D8: m3 | E8: Carga y Retiro de Escombros | F8: =ROUNDDOWN(1.3*2442*0.3,0) -> 952 | G8: 15000 | H8: =ROUND(F8*G8,3) -> 14280000 | J8: =F8*$F$4 -> 952 | K8: =H8*$F$4 -> 14280000
E9: Total APU 1.1 | F9: =$F$4 -> 1 | G9: =SUM(H5:H8) -> 19164000 | H9: =ROUND(F9*G9,3) -> 19164000 | K9: =SUM(K5:K8) -> 19164000

Sheet 2.1
B1: 02.- Presupuesto'!A1
B3: Código | C3: Recurso | D3: Unidad | E3: Descripción | F3: Cantidad | G3: Precio Unitario | H3: Total | M3: Mat | N3: MO | O3: SC | P3: Arr
B4: 2.1 | C4: Partida | D4: ='01.- Presupuesto'!F18 -> m3 | E4: ='01.- Presupuesto'!C18 -> Excavación, carguió sobre camión y traslado a botadero, e = variable | F4: ='01.- Presupuesto'!G18 -> 890 | G4: =G9 -> 25500 | H4: =H9 -> 22695000 | J4: Cantidad | K4: Costo | M4: =SUMIF(C5:C21,"Material",K5:K21) -> 0 | N4: =SUMIF(C5:C21,"Mano de Obra",K5:K21) -> 0 | O4: =SUMIF(C5:C21,"Subcontrato",K5:K21) -> 0 | P4: =SUMIF(C5:C21,"Ser&Arr",K5:K21) -> 22695000 | Q4: =SUM(M4:P4) -> 22695000
C5: Ser&Arr | D5: hm | E5: Excavadora | F5: =1/20 -> 0.05 | G5: =Excavadora -> 50000 | H5: =ROUND(F5*G5,3) -> 2500 | J5: =F5*$F$4 -> 44.5 | K5: =H5*$F$4 -> 2225000
C6: Ser&Arr | D6: hm | E6: Retroexcavadora | F6: =1/20 -> 0.05 | G6: =Retroexcavadora -> 32000 | H6: =ROUND(F6*G6,3) -> 1600 | J6: =F6*$F$4 -> 44.5 | K6: =H6*$F$4 -> 1424000
C7: Ser&Arr | D7: hm | E7: Camión Tolva | F7: =1/20 -> 0.05 | G7: =Tolva -> 38000 | H7: =ROUND(F7*G7,3) -> 1900 | J7: =F7*$F$4 -> 44.5 | K7: =H7*$F$4 -> 1691000
C8: Ser&Arr | D8: m3 | E8: Carga y Retiro de Escombros | F8: 1.3 | G8: 15000 | H8: =ROUND(F8*G8,3) -> 19500 | J8: =F8*$F$4 -> 1157 | K8: =H8*$F$4 -> 17355000
E9: Total APU 2.1 | F9: =$F$4 -> 890 | G9: =SUM(H5:H8) -> 25500 | H9: =ROUND(F9*G9,3) -> 22695000 | K9: =SUM(K5:K8) -> 22695000

Sheet 2.2
B1: 02.- Presupuesto'!A1
B3: Código | C3: Recurso | D3: Unidad | E3: Descripción | F3: Cantidad | G3: Precio Unitario | H3: Total | M3: Mat | N3: MO | O3: SC | P3: Arr
B4: 2.2 | C4: Partida | D4: ='01.- Presupuesto'!F19 -> m3 | E4: ='01.- Presupuesto'!C19 -> Retiro y reposición zanja para ducto malla de puesta a tierra | F4: ='01.- Presupuesto'!G19 -> 400 | G4: =G15 -> 34101.438 | H4: =H15 -> 13640575 | J4: Cantidad | K4: Costo | M4: =SUMIF(C5:C27,"Material",K5:K27) -> 10400000 | N4: =SUMIF(C5:C27,"Mano de Obra",K5:K27) -> 1153555.6 | O4: =SUMIF(C5:C27,"Subcontrato",K5:K27) -> 0 | P4: =SUMIF(C5:C27,"Ser&Arr",K5:K27) -> 2087019.6 | Q4: =SUM(M4:P4) -> 13640575
C5: Material | D5: m3 | E5: Base Granular CBR >50% | F5: 1.3 | G5: =Base50 -> 20000 | H5: =ROUND(F5*G5,3) -> 26000 | J5: =F5*$F$4 -> 520 | K5: =H5*$F$4 -> 10400000
C6: Mano de Obra | D6: hh | E6: Maestro | F6: =2*1/20 -> 0.1 | G6: =Maestro -> 7250 | H6: =ROUND(F6*G6,3) -> 725 | J6: =F6*$F$4 -> 40 | K6: =H6*$F$4 -> 290000
C7: Mano de Obra | D7: hh | E7: Jornal | F7: =2*4*1/20 -> 0.4 | G7: =Jornal -> 5397.2222 | H7: =ROUND(F7*G7,3) -> 2158.889 | J7: =F7*$F$4 -> 160 | K7: =H7*$F$4 -> 863555.6
C8: Ser&Arr | D8: % | E8: Desgaste de Herramientas | F8: 0.2 | G8: =SUM(H6:H7) -> 2883.889 | H8: =ROUND(F8*G8,3) -> 576.778 | J8: =F8*$F$4 -> 80 | K8: =H8*$F$4 -> 230711.2
C9: Ser&Arr | D9: un | E9: Chuzo | F9: 0.01 | G9: 17100 | H9: =ROUND(F9*G9,3) -> 171 | J9: =F9*$F$4 -> 4 | K9: =H9*$F$4 -> 68400
C10: Ser&Arr | D10: un | E10: Pala Punta Huevo | F10: 0.01 | G10: 7000 | H10: =ROUND(F10*G10,3) -> 70 | J10: =F10*$F$4 -> 4 | K10: =H10*$F$4 -> 28000
C11: Ser&Arr | D11: hm | E11: Retroexcavadora | F11: =2*1/20 -> 0.1 | G11: =Retroexcavadora -> 32000 | H11: =ROUND(F11*G11,3) -> 3200 | J11: =F11*$F$4 -> 40 | K11: =H11*$F$4 -> 1280000
C12: Ser&Arr | D12: día | E12: Placa Compactadora | F12: =1/20/8 -> 0.00625 | G12: 25000 | H12: =ROUND(F12*G12,3) -> 156.25 | J12: =F12*$F$4 -> 2.5 | K12: =H12*$F$4 -> 62500
C13: Ser&Arr | D13: un | E13: Ensayo Granulometría | F13: =1/F4 -> 0.0025 | G13: =(0.6+4.4)*UF -> 196335 | H13: =ROUND(F13*G13,3) -> 490.838 | J13: =F13*$F$4 -> 1 | K13: =H13*$F$4 -> 196335.2
C14: Ser&Arr | D14: un | E14: Ensayo Densidad In Situ | F14: =3/F4 -> 0.0075 | G14: =(0.41+4.4/3)*UF -> 73691.07 | H14: =ROUND(F14*G14,3) -> 552.683 | J14: =F14*$F$4 -> 3 | K14: =H14*$F$4 -> 221073.2
E15: Total APU 2.2 | F15: =$F$4 -> 400 | G15: =SUM(H5:H14) -> 34101.438 | H15: =ROUND(F15*G15,3) -> 13640575 | K15: =SUM(K5:K14) -> 13640575

Sheet 2.3
B1: 02.- Presupuesto'!A1
B3: Código | C3: Recurso | D3: Unidad | E3: Descripción | F3: Cantidad | G3: Precio Unitario | H3: Total | M3: Mat | N3: MO | O3: SC | P3: Arr
B4: 2.3 | C4: Partida | D4: ='01.- Presupuesto'!F20 -> m3 | E4: ='01.- Presupuesto'!C20 -> Formación y compactación de plataforma e= variable. Relleno e= 20cm | F4: ='01.- Presupuesto'!G20 -> 754 | G4: =G18 -> 67330.534 | H4: =H18 -> 50767223 | J4: Cantidad | K4: Costo | M4: =SUMIF(C5:C30,"Material",K5:K30) -> 42295257 | N4: =SUMIF(C5:C30,"Mano de Obra",K5:K30) -> 1961044.4 | O4: =SUMIF(C5:C30,"Subcontrato",K5:K30) -> 0 | P4: =SUMIF(C5:C30,"Ser&Arr",K5:K30) -> 6510921.2 | Q4: =SUM(M4:P4) -> 50767223
C5: Material | D5: m3 | E5: Base Granular CBR >100% | F5: 1.3 | G5: =Base100 -> 22000 | H5: =ROUND(F5*G5,3) -> 28600 | J5: =F5*$F$4 -> 980.2 | K5: =H5*$F$4 -> 21564400
C6: Ser&Arr | D6: hm | E6: Retroexcavadora | F6: =1/20 -> 0.05 | G6: =Retroexcavadora -> 32000 | H6: =ROUND(F6*G6,3) -> 1600 | J6: =F6*$F$4 -> 37.7 | K6: =H6*$F$4 -> 1206400
C7: Ser&Arr | D7: hm | E7: Rodillo | F7: =1/20 -> 0.05 | G7: =Rodillo -> 42000 | H7: =ROUND(F7*G7,3) -> 2100 | J7: =F7*$F$4 -> 37.7 | K7: =H7*$F$4 -> 1583400
C8: Ser&Arr | D8: hm | E8: Camión Aljibe | F8: =1/20 -> 0.05 | G8: =Aljibe -> 32000 | H8: =ROUND(F8*G8,3) -> 1600 | J8: =F8*$F$4 -> 37.7 | K8: =H8*$F$4 -> 1206400
C9: Ser&Arr | D9: un | E9: Ensayo Granulometría | F9: =1/F4 -> 0.0013262599 | G9: =(0.6+4.4)*UF -> 196335 | H9: =ROUND(F9*G9,3) -> 260.391 | J9: =F9*$F$4 -> 1 | K9: =H9*$F$4 -> 196334.81
C10: Ser&Arr | D10: un | E10: Ensayo Proctor | F10: =1/F4 -> 0.0013262599 | G10: =1.3*UF -> 51047.1 | H10: =ROUND(F10*G10,3) -> 67.702 | J10: =F10*$F$4 -> 1 | K10: =H10*$F$4 -> 51047.308
C11: Ser&Arr | D11: un | E11: Ensayo CBR | F11: =1/50 -> 0.02 | G11: =(1.7+4.4/3)*UF -> 124345.5 | H11: =ROUND(F11*G11,3) -> 2486.91 | J11: =F11*$F$4 -> 15.08 | K11: =H11*$F$4 -> 1875130.1
B12: 2.3.1 | C12: Partida | D12: m | E12: Gaviones | F12: =68/F4 -> 0.090185676 | G12: =SUM(H13:H17) -> 339472.21 | H12: =G12*F12 -> 30615.531
C13: Material | D13: un | E13: Gaviones | F13: =6/2 -> 3 | G13: =54290/1.19 -> 45621.849 | H13: =ROUND(F13*G13,3) -> 136865.55 | J13: =F13*$F$4*F12 -> 204 | K13: =G13*J13 -> 9306857.1
C14: Material | D14: m3 | E14: Grava | F14: =1*1*6 -> 6 | G14: =Grava -> 28000 | H14: =ROUND(F14*G14,3) -> 168000 | J14: =F14*$F$4*F12 -> 408 | K14: =G14*J14 -> 11424000
C15: Mano de Obra | D15: hh | E15: Maestro | F15: 1 | G15: =Maestro -> 7250 | H15: =ROUND(F15*G15,3) -> 7250 | J15: =F15*$F$4*F12 -> 68 | K15: =G15*J15 -> 493000
C16: Mano de Obra | D16: hh | E16: Jornal | F16: 4 | G16: =Jornal -> 5397.2222 | H16: =ROUND(F16*G16,3) -> 21588.889 | J16: =F16*$F$4*F12 -> 272 | K16: =G16*J16 -> 1468044.4
C17: Ser&Arr | D17: % | E17: Desgaste de Herramientas | F17: 0.2 | G17: =SUM(H15:H16) -> 28838.889 | H17: =ROUND(F17*G17,3) -> 5767.778 | J17: =F17*$F$4*F12 -> 13.6 | K17: =G17*J17 -> 392208.89
E18: Total APU 2.3 | F18: =$F$4 -> 754 | G18: =SUM(H5:H12) -> 67330.534 | H18: =ROUND(F18*G18,3) -> 50767223 | K18: =SUM(K5:K17) -> 50767223

Sheet 2.4
B1: 02.- Presupuesto'!A1
B3: Código | C3: Recurso | D3: Unidad | E3: Descripción | F3: Cantidad | G3: Precio Unitario | H3: Total | M3: Mat | N3: MO | O3: SC | P3: Arr
B4: 2.4 | C4: Partida | D4: ='01.- Presupuesto'!F21 -> gl | E4: ='01.- Presupuesto'!C21 -> Tratamiento de taludes de corte con hidrosiembra según manual de carreteras | F4: ='01.- Presupuesto'!G21 -> 1 | G4: =G6 -> 42742 | H4: =H6 -> 42742 | J4: Cantidad | K4: Costo | M4: =SUMIF(C5:C18,"Material",K5:K18) -> 0 | N4: =SUMIF(C5:C18,"Mano de Obra",K5:K18) -> 0 | O4: =SUMIF(C5:C18,"Subcontrato",K5:K18) -> 42742 | P4: =SUMIF(C5:C18,"Ser&Arr",K5:K18) -> 0 | Q4: =SUM(M4:P4) -> 42742
C5: Subcontrato | D5: m2 | E5: Subcontrato Tratamiento con Hidrosembrado | F5: 1 | G5: =SCHidrosembrado -> 42742 | H5: =ROUND(F5*G5,3) -> 42742 | J5: =F5*$F$4 -> 1 | K5: =H5*$F$4 -> 42742
E6: Total APU 2.4 | F6: =$F$4 -> 1 | G6: =SUM(H5:H5) -> 42742 | H6: =ROUND(F6*G6,3) -> 42742 | K6: =SUM(K5:K5) -> 42742

Sheet 3.1
B1: 02.- Presupuesto'!A1
B3: Código | C3: Recurso | D3: Unidad | E3: Descripción | F3: Cantidad | G3: Precio Unitario | H3: Total | M3: Mat | N3: MO | O3: SC | P3: Arr
B4: 3.1 | C4: Partida | D4: ='01.- Presupuesto'!F23 -> m3 | E4: ='01.- Presupuesto'!C23 -> Sobrexcavación para caminos interiores, carguio sobre camión y traslado | F4: ='01.- Presupuesto'!G23 -> 760 | G4: =G9 -> 25500 | H4: =H9 -> 19380000 | J4: Cantidad | K4: Costo | M4: =SUMIF(C5:C21,"Material",K5:K21) -> 0 | N4: =SUMIF(C5:C21,"Mano de Obra",K5:K21) -> 0 | O4: =SUMIF(C5:C21,"Subcontrato",K5:K21) -> 0 | P4: =SUMIF(C5:C21,"Ser&Arr",K5:K21) -> 19380000 | Q4: =SUM(M4:P4) -> 19380000
C5: Ser&Arr | D5: hm | E5: Excavadora | F5: =1/20 -> 0.05 | G5: =Excavadora -> 50000 | H5: =ROUND(F5*G5,3) -> 2500 | J5: =F5*$F$4 -> 38 | K5: =H5*$F$4 -> 1900000
C6: Ser&Arr | D6: hm | E6: Retroexcavadora | F6: =1/20 -> 0.05 | G6: =Retroexcavadora -> 32000 | H6: =ROUND(F6*G6,3) -> 1600 | J6: =F6*$F$4 -> 38 | K6: =H6*$F$4 -> 1216000
C7: Ser&Arr | D7: hm | E7: Camión Tolva | F7: =1/20 -> 0.05 | G7: =Tolva -> 38000 | H7: =ROUND(F7*G7,3) -> 1900 | J7: =F7*$F$4 -> 38 | K7: =H7*$F$4 -> 1444000
C8: Ser&Arr | D8: m3 | E8: Carga y Retiro de Escombros | F8: 1.3 | G8: 15000 | H8: =ROUND(F8*G8,3) -> 19500 | J8: =F8*$F$4 -> 988 | K8: =H8*$F$4 -> 14820000
E9: Total APU 3.1 | F9: =$F$4 -> 760 | G9: =SUM(H5:H8) -> 25500 | H9: =ROUND(F9*G9,3) -> 19380000 | K9: =SUM(K5:K8) -> 19380000

Sheet 3.2
B1: 02.- Presupuesto'!A1
B3: Código | C3: Recurso | D3: Unidad | E3: Descripción | F3: Cantidad | G3: Precio Unitario | H3: Total | M3: Mat | N3: MO | O3: SC | P3: Arr
B4: 3.2 | C4: Partida | D4: ='01.- Presupuesto'!F24 -> m3 | E4: ='01.- Presupuesto'!C24 -> Suministro y colocación Base Granular CBR >100% e=26cm | F4: ='01.- Presupuesto'!G24 -> 234 | G4: =G12 -> 37444.098 | H4: =H12 -> 8761918.9 | J4: Cantidad | K4: Costo | M4: =SUMIF(C5:C24,"Material",K5:K24) -> 6692400 | N4: =SUMIF(C5:C24,"Mano de Obra",K5:K24) -> 0 | O4: =SUMIF(C5:C24,"Subcontrato",K5:K24) -> 0 | P4: =SUMIF(C5:C24,"Ser&Arr",K5:K24) -> 2069518.9 | Q4: =SUM(M4:P4) -> 8761918.9
C5: Material | D5: m3 | E5: Base Granular CBR >100% | F5: 1.3 | G5: =Base100 -> 22000 | H5: =ROUND(F5*G5,3) -> 28600 | J5: =F5*$F$4 -> 304.2 | K5: =H5*$F$4 -> 6692400
C6: Ser&Arr | D6: hm | E6: Retroexcavadora | F6: =1/20 -> 0.05 | G6: =Retroexcavadora -> 32000 | H6: =ROUND(F6*G6,3) -> 1600 | J6: =F6*$F$4 -> 11.7 | K6: =H6*$F$4 -> 374400
C7: Ser&Arr | D7: hm | E7: Rodillo | F7: =1/20 -> 0.05 | G7: =Rodillo -> 42000 | H7: =ROUND(F7*G7,3) -> 2100 | J7: =F7*$F$4 -> 11.7 | K7: =H7*$F$4 -> 491400
C8: Ser&Arr | D8: hm | E8: Camión Aljibe | F8: =1/20 -> 0.05 | G8: =Aljibe -> 32000 | H8: =ROUND(F8*G8,3) -> 1600 | J8: =F8*$F$4 -> 11.7 | K8: =H8*$F$4 -> 374400
C9: Ser&Arr | D9: un | E9: Ensayo Granulometría | F9: =1/F4 -> 0.0042735043 | G9: =(0.6+4.4)*UF -> 196335 | H9: =ROUND(F9*G9,3) -> 839.038 | J9: =F9*$F$4 -> 1 | K9: =H9*$F$4 -> 196334.89
C10: Ser&Arr | D10: un | E10: Ensayo Proctor | F10: =1/F4 -> 0.0042735043 | G10: =1.3*UF -> 51047.1 | H10: =ROUND(F10*G10,3) -> 218.15 | J10: =F10*$F$4 -> 1 | K10: =H10*$F$4 -> 51047.1
C11: Ser&Arr | D11: un | E11: Ensayo CBR | F11: =1/50 -> 0.02 | G11: =(1.7+4.4/3)*UF -> 124345.5 | H11: =ROUND(F11*G11,3) -> 2486.91 | J11: =F11*$F$4 -> 4.68 | K11: =H11*$F$4 -> 581936.94
E12: Total APU 3.2 | F12: =$F$4 -> 234 | G12: =SUM(H5:H11) -> 37444.098 | H12: =ROUND(F12*G12,3) -> 8761918.9 | K12: =SUM(K5:K11) -> 8761918.9

Sheet 3.3
B1: 02.- Presupuesto'!A1
B3: Código | C3: Recurso | D3: Unidad | E3: Descripción | F3: Cantidad | G3: Precio Unitario | H3: Total | M3: Mat | N3: MO | O3: SC | P3: Arr
B4: 3.3 | C4: Partida | D4: ='01.- Presupuesto'!F25 -> m3 | E4: ='01.- Presupuesto'!C25 -> Suministro y colocación Sub-Base granular CBR > 50% e=20cm | F4: ='01.- Presupuesto'!G25 -> 180 | G4: =G12 -> 35161.255 | H4: =H12 -> 6329025.9 | J4: Cantidad | K4: Costo | M4: =SUMIF(C5:C24,"Material",K5:K24) -> 4680000 | N4: =SUMIF(C5:C24,"Mano de Obra",K5:K24) -> 0 | O4: =SUMIF(C5:C24,"Subcontrato",K5:K24) -> 0 | P4: =SUMIF(C5:C24,"Ser&Arr",K5:K24) -> 1649025.9 | Q4: =SUM(M4:P4) -> 6329025.9
C5: Material | D5: m3 | E5: Base Granular CBR >50% | F5: 1.3 | G5: =Base50 -> 20000 | H5: =ROUND(F5*G5,3) -> 26000 | J5: =F5*$F$4 -> 234 | K5: =H5*$F$4 -> 4680000
C6: Ser&Arr | D6: hm | E6: Retroexcavadora | F6: =1/20 -> 0.05 | G6: =Retroexcavadora -> 32000 | H6: =ROUND(F6*G6,3) -> 1600 | J6: =F6*$F$4 -> 9 | K6: =H6*$F$4 -> 288000
C7: Ser&Arr | D7: hm | E7: Rodillo | F7: =1/20 -> 0.05 | G7: =Rodillo -> 42000 | H7: =ROUND(F7*G7,3) -> 2100 | J7: =F7*$F$4 -> 9 | K7: =H7*$F$4 -> 378000
C8: Ser&Arr | D8: hm | E8: Camión Aljibe | F8: =1/20 -> 0.05 | G8: =Aljibe -> 32000 | H8: =ROUND(F8*G8,3) -> 1600 | J8: =F8*$F$4 -> 9 | K8: =H8*$F$4 -> 288000
C9: Ser&Arr | D9: un | E9: Ensayo Granulometría | F9: =1/F4 -> 0.0055555556 | G9: =(0.6+4.4)*UF -> 196335 | H9: =ROUND(F9*G9,3) -> 1090.75 | J9: =F9*$F$4 -> 1 | K9: =H9*$F$4 -> 196335
C10: Ser&Arr | D10: un | E10: Ensayo Proctor | F10: =1/F4 -> 0.0055555556 | G10: =1.3*UF -> 51047.1 | H10: =ROUND(F10*G10,3) -> 283.595 | J10: =F10*$F$4 -> 1 | K10: =H10*$F$4 -> 51047.1
C11: Ser&Arr | D11: un | E11: Ensayo CBR | F11: =1/50 -> 0.02 | G11: =(1.7+4.4/3)*UF -> 124345.5 | H11: =ROUND(F11*G11,3) -> 2486.91 | J11: =F11*$F$4 -> 3.6 | K11: =H11*$F$4 -> 447643.8
E12: Total APU 3.3 | F12: =$F$4 -> 180 | G12: =SUM(H5:H11) -> 35161.255 | H12: =ROUND(F12*G12,3) -> 6329025.9 | K12: =SUM(K5:K11) -> 6329025.9

Sheet 3.4
B1: 02.- Presupuesto'!A1
B3: Código | C3: Recurso | D3: Unidad | E3: Descripción | F3: Cantidad | G3: Precio Unitario | H3: Total | M3: Mat | N3: MO | O3: SC | P3: Arr
B4: 3.4 | C4: Partida | D4: ='01.- Presupuesto'!F26 -> m3 | E4: ='01.- Presupuesto'!C26 -> Suministro y colocación de bolones para estabilización de suelos e=30cm | F4: ='01.- Presupuesto'!G26 -> 270 | G4: =G7 -> 49700 | H4: =H7 -> 13419000 | J4: Cantidad | K4: Costo | M4: =SUMIF(C5:C19,"Material",K5:K19) -> 12987000 | N4: =SUMIF(C5:C19,"Mano de Obra",K5:K19) -> 0 | O4: =SUMIF(C5:C19,"Subcontrato",K5:K19) -> 0 | P4: =SUMIF(C5:C19,"Ser&Arr",K5:K19) -> 432000 | Q4: =SUM(M4:P4) -> 13419000
C5: Material | D5: m3 | E5: Bolones | F5: 1.3 | G5: =Bolones -> 37000 | H5: =ROUND(F5*G5,3) -> 48100 | J5: =F5*$F$4 -> 351 | K5: =H5*$F$4 -> 12987000
C6: Ser&Arr | D6: hm | E6: Retroexcavadora | F6: =1/20 -> 0.05 | G6: =Retroexcavadora -> 32000 | H6: =ROUND(F6*G6,3) -> 1600 | J6: =F6*$F$4 -> 13.5 | K6: =H6*$F$4 -> 432000
E7: Total APU 3.4 | F7: =$F$4 -> 270 | G7: =SUM(H5:H6) -> 49700 | H7: =ROUND(F7*G7,3) -> 13419000 | K7: =SUM(K5:K6) -> 13419000

Sheet 3.5
B1: 02.- Presupuesto'!A1
B3: Código | C3: Recurso | D3: Unidad | E3: Descripción | F3: Cantidad | G3: Precio Unitario | H3: Total | M3: Mat | N3: MO | O3: SC | P3: Arr
B4: 3.5 | C4: Partida | D4: ='01.- Presupuesto'!F27 -> m2 | E4: ='01.- Presupuesto'!C27 -> Suministro e Instalación de Geotextil bajo la Sub-Base | F4: ='01.- Presupuesto'!G27 -> 900 | G4: =G9 -> 1623.533 | H4: =H9 -> 1461179.7 | J4: Cantidad | K4: Costo | M4: =SUMIF(C5:C21,"Material",K5:K21) -> 1188000 | N4: =SUMIF(C5:C21,"Mano de Obra",K5:K21) -> 227649.6 | O4: =SUMIF(C5:C21,"Subcontrato",K5:K21) -> 0 | P4: =SUMIF(C5:C21,"Ser&Arr",K5:K21) -> 45530.1 | Q4: =SUM(M4:P4) -> 1461179.7
C5: Material | D5: uni | E5: Malla Geotextil 2x50 | F5: =1/(2*50)*1.1 -> 0.011 | G5: 120000 | H5: =ROUND(F5*G5,3) -> 1320 | J5: =F5*$F$4 -> 9.9 | K5: =H5*$F$4 -> 1188000
C6: Mano de Obra | D6: hh | E6: Maestro | F6: =1/50 -> 0.02 | G6: =Maestro -> 7250 | H6: =ROUND(F6*G6,3) -> 145 | J6: =F6*$F$4 -> 18 | K6: =H6*$F$4 -> 130500
C7: Mano de Obra | D7: hh | E7: Jornal | F7: =1/50 -> 0.02 | G7: =Jornal -> 5397.2222 | H7: =ROUND(F7*G7,3) -> 107.944 | J7: =F7*$F$4 -> 18 | K7: =H7*$F$4 -> 97149.6
C8: Ser&Arr | D8: % | E8: Desgaste de Herramientas | F8: 0.2 | G8: =SUM(H6:H7) -> 252.944 | H8: =ROUND(F8*G8,3) -> 50.589 | J8: =F8*$F$4 -> 180 | K8: =H8*$F$4 -> 45530.1
E9: Total APU 3.5 | F9: =$F$4 -> 900 | G9: =SUM(H5:H8) -> 1623.533 | H9: =ROUND(F9*G9,3) -> 1461179.7 | K9: =SUM(K5:K8) -> 1461179.7

Sheet 4.1
B1: 02.- Presupuesto'!A1
B3: Código | C3: Recurso | D3: Unidad | E3: Descripción | F3: Cantidad | G3: Precio Unitario | H3: Total | M3: Mat | N3: MO | O3: SC | P3: Arr
B4: 4.1 | C4: Partida | D4: ='01.- Presupuesto'!F29 -> m | E4: ='01.- Presupuesto'!C29 -> Suministro de materiales y construcción de zanja de infiltración, incluye cubo dren | F4: ='01.- Presupuesto'!G29 -> 6.3 | G4: =G50 -> 315982.17 | H4: =H50 -> 1990687.6 | J4: Cantidad | K4: Costo | M4: =SUMIF(C5:C48,"Material",K5:K55) -> 680431.52 | N4: =SUMIF(C5:C48,"Mano de Obra",K5:K55) -> 241535.93 | O4: =SUMIF(C5:C48,"Subcontrato",K5:K55) -> 767550 | P4: =SUMIF(C5:C48,"Ser&Arr",K5:K55) -> 301170.2 | Q4: =SUM(M4:P4) -> 1990687.6
B5: 13.1 | C5: Partida | D5: ='13.1'!$D$4 -> m3 | E5: ='13.1'!$E$4 -> Suministro y colocación arena limpia compactada | F5: =((1.16*(0.3+0.425*2)*F4)-(F21*F4*0.425*0.38*0.79))/F4 -> 0.68594921 | G5: ='13.1'!$G$4 -> 34686.583 | H5: =H12 -> 23793.234
C6: Material | D6: m3 | E6: Arena | F6: 1.3 | G6: =Arena -> 24000 | H6: =ROUND(F6*G6,3) -> 31200 | J6: =F6*$F$5*$F$4 -> 5.617924 | K6: =J6*G6 -> 134830.18
C7: Mano de Obra | D7: hh | E7: Maestro | F7: =1/20 -> 0.05 | G7: =Maestro -> 7250 | H7: =ROUND(F7*G7,3) -> 362.5 | J7: =F7*$F$5*$F$4 -> 0.216074 | K7: =J7*G7 -> 1566.5365
C8: Mano de Obra | D8: hh | E8: Jornal | F8: =4*1/20 -> 0.2 | G8: =Jornal -> 5397.2222 | H8: =ROUND(F8*G8,3) -> 1079.444 | J8: =F8*$F$5*$F$4 -> 0.864296 | K8: =J8*G8 -> 4664.7976
C9: Ser&Arr | D9: % | E9: Desgaste de Herramientas | F9: 0.2 | G9: =SUM(H7:H8) -> 1441.944 | H9: =ROUND(F9*G9,3) -> 288.389 | J9: =F9*$F$5*$F$4 -> 0.864296 | K9: =J9*G9 -> 1246.2664
C10: Ser&Arr | D10: hm | E10: Retroexcavadora | F10: =1/20 -> 0.05 | G10: =Retroexcavadora -> 32000 | H10: =ROUND(F10*G10,3) -> 1600 | J10: =F10*$F$5*$F$4 -> 0.216074 | K10: =J10*G10 -> 6914.368
C11: Ser&Arr | D11: día | E11: Placa Compactadora | F11: =1/20/8 -> 0.00625 | G11: 25000 | H11: =ROUND(F11*G11,3) -> 156.25 | J11: =F11*$F$5*$F$4 -> 0.02700925 | K11: =J11*G11 -> 675.23125
E12: Total APU 13.1 | F12: =F5 -> 0.68594921 | G12: =SUM(H6:H11) -> 34686.583 | H12: =ROUND(F12*G12,3) -> 23793.234
B13: 13.2 | C13: Partida | D13: ='13.2'!$D$4 -> m3 | E13: ='13.2'!$E$4 -> Suministro y colocación gravilla (bajo tamiz 1") | F13: =1.16*0.2 -> 0.232 | G13: ='13.2'!$G$4 -> 37286.583 | H13: =H20 -> 8650.487
C14: Material | D14: m3 | E14: Gravilla | F14: 1.3 | G14: =Gravilla -> 26000 | H14: =ROUND(F14*G14,3) -> 33800 | J14: =F14*$F$13*$F$4 -> 1.90008 | K14: =J14*G14 -> 49402.08
C15: Mano de Obra | D15: hh | E15: Maestro | F15: =1/20 -> 0.05 | G15: =Maestro -> 7250 | H15: =ROUND(F15*G15,3) -> 362.5 | J15: =F15*$F$13*$F$4 -> 0.07308 | K15: =J15*G15 -> 529.83
C16: Mano de Obra | D16: hh | E16: Jornal | F16: =4*1/20 -> 0.2 | G16: =Jornal -> 5397.2222 | H16: =ROUND(F16*G16,3) -> 1079.444 | J16: =F16*$F$13*$F$4 -> 0.29232 | K16: =J16*G16 -> 1577.716
C17: Ser&Arr | D17: % | E17: Desgaste de Herramientas | F17: 0.2 | G17: =SUM(H15:H16) -> 1441.944 | H17: =ROUND(F17*G17,3) -> 288.389 | J17: =F17*$F$13*$F$4 -> 0.29232 | K17: =J17*G17 -> 421.50907
C18: Ser&Arr | D18: hm | E18: Retroexcavadora | F18: =1/20 -> 0.05 | G18: =Retroexcavadora -> 32000 | H18: =ROUND(F18*G18,3) -> 1600 | J18: =F18*$F$13*$F$4 -> 0.07308 | K18: =J18*G18 -> 2338.56
C19: Ser&Arr | D19: día | E19: Placa Compactadora | F19: =1/20/8 -> 0.00625 | G19: 25000 | H19: =ROUND(F19*G19,3) -> 156.25 | J19: =F19*$F$13*$F$4 -> 0.009135 | K19: =J19*G19 -> 228.375
E20: Total APU 13.2 | F20: =F13 -> 0.232 | G20: =SUM(H14:H19) -> 37286.583 | H20: =ROUND(F20*G20,3) -> 8650.487
B21: 13.3 | C21: Partida | D21: ='13.3'!$D$4 -> un | E21: ='13.3'!$E$4 -> Suministro e instalación Cubos dren 26 t/m2 | F21: =(4*ROUNDUP((F4/0.79),0))/F4 -> 5.0793651 | G21: ='13.3'!$G$4 -> 18599.722 | H21: =H25 -> 94474.778
C22: Material | D22: uni | E22: Cubo Drenaje INSYTEC Serie 3000 16/26T 0,425 x 0,38 x 0,79 m | F22: 1 | G22: =CuboDren -> 11390 | H22: =ROUND(F22*G22,3) -> 11390 | J22: =F22*$F$21*$F$4 -> 32 | K22: =J22*G22 -> 364480
C23: Mano de Obra | D23: hh | E23: Maestro | F23: =1/4 -> 0.25 | G23: =Maestro -> 7250 | H23: =ROUND(F23*G23,3) -> 1812.5 | J23: =F23*$F$21*$F$4 -> 8 | K23: =J23*G23 -> 58000
C24: Mano de Obra | D24: hh | E24: Jornal | F24: 1 | G24: =Jornal -> 5397.2222 | H24: =ROUND(F24*G24,3) -> 5397.222 | J24: =F24*$F$21*$F$4 -> 32 | K24: =J24*G24 -> 172711.11
E25: Total APU 13.3 | F25: =F21 -> 5.0793651 | G25: =SUM(H22:H24) -> 18599.722 | H25: =ROUND(F25*G25,3) -> 94474.778
B26: 13.4 | C26: Partida | D26: ='13.4'!$D$4 -> m3 | E26: ='13.4'!$E$4 -> Excavación máquinaria local, traslado a botadero hasta 20km (geométrica, sin esponajamiento) | F26: =((1.16*(0.3+0.425*2+0.4)*F4))/F4 -> 1.798 | G26: ='13.4'!$G$4 -> 25500 | H26: =H31 -> 45849
C27: Ser&Arr | D27: hm | E27: Excavadora | F27: =1/20 -> 0.05 | G27: =Excavadora -> 50000 | H27: =ROUND(F27*G27,3) -> 2500 | J27: =F27*$F$26*$F$4 -> 0.56637 | K27: =J27*G27 -> 28318.5
C28: Ser&Arr | D28: hm | E28: Retroexcavadora | F28: =1/20 -> 0.05 | G28: =Retroexcavadora -> 32000 | H28: =ROUND(F28*G28,3) -> 1600 | J28: =F28*$F$26*$F$4 -> 0.56637 | K28: =J28*G28 -> 18123.84
C29: Ser&Arr | D29: hm | E29: Camión Tolva | F29: =1/20 -> 0.05 | G29: =Tolva -> 38000 | H29: =ROUND(F29*G29,3) -> 1900 | J29: =F29*$F$26*$F$4 -> 0.56637 | K29: =J29*G29 -> 21522.06
C30: Ser&Arr | D30: m3 | E30: Carga y Retiro de Escombros | F30: 1.3 | G30: 15000 | H30: =ROUND(F30*G30,3) -> 19500 | J30: =F30*$F$26*$F$4 -> 14.72562 | K30: =J30*G30 -> 220884.3
E31: Total APU 13.4 | F31: =F26 -> 1.798 | G31: =SUM(H27:H30) -> 25500 | H31: =ROUND(F31*G31,3) -> 45849
B32: 13.5 | C32: Partida | D32: ='13.5'!$D$4 -> m | E32: ='13.5'!$E$4 -> Suministro e instalación PVC 110mm | F32: 6 | G32: ='13.5'!$G$4 -> 19571.289 | H32: =H35 -> 117427.73
C33: Material | D33: uni | E33: Tubería PVC 110 mm Sanitario | F33: =1.1*1/6 -> 0.18333333 | G33: =16690/1.19 -> 14025.21 | H33: =ROUND(F33*G33,3) -> 2571.289 | J33: =F33*F32*$F$4 -> 6.93 | K33: =J33*G33 -> 97194.706
C34: Subcontrato | D34: m | E34: SC Instalación Tuberías PVC | F34: 1 | G34: =SCSan -> 17000 | H34: =ROUND(F34*G34,3) -> 17000 | J34: =F34*F32*$F$4 -> 37.8 | K34: =J34*G34 -> 642600
E35: Total APU 13.5 | F35: =F32 -> 6 | G35: =SUM(H33:H34) -> 19571.289 | H35: =ROUND(F35*G35,3) -> 117427.73
B36: 13.6 | C36: Partida | D36: ='13.6'!$D$4 -> un | E36: ='13.6'!$E$4 -> Suministro e instalación códo de PVC 110mm | F36: 1 | G36: ='13.6'!$G$4 -> 2698.506 | H36: =H39 -> 3170.728
C37: Material | D37: uni | E37: Codo PVC 110 mm Sanitario | F37: =1.1*1/6 -> 0.18333333 | G37: =2190/1.19 -> 1840.3361 | H37: =ROUND(F37*G37,3) -> 337.395 | J37: =F37*F36*$F$4 -> 1.155 | K37: =J37*G37 -> 2125.5882
C38: Subcontrato | D38: m | E38: SC Instalación Tuberías PVC | F38: =F36/F32 -> 0.16666667 | G38: =SCSan -> 17000 | H38: =ROUND(F38*G38,3) -> 2833.333 | J38: =F38*F36*$F$4 -> 1.05 | K38: =J38*G38 -> 17850
E39: Total APU 13.6 | F39: =F36 -> 1 | G39: =SUM(H37:H38) -> 3170.728 | H39: =ROUND(F39*G39,3) -> 3170.728
B40: 13.7 | C40: Partida | D40: ='13.7'!$D$4 -> m2 | E40: ='13.7'!$E$4 -> Suministro e instalación de Geotextil | F40: =1.16+0.4 -> 1.56 | G40: ='13.7'!$G$4 -> 1623.533 | H40: =H45 -> 2532.711
C41: Material | D41: uni | E41: Malla Geotextil 2x50 | F41: =1/(2*50)*1.1 -> 0.011 | G41: 120000 | H41: =ROUND(F41*G41,3) -> 1320 | J41: =F41*$F$40*$F$4 -> 0.108108 | K41: =J41*G41 -> 12972.96
...

Sheet 4.2
B1: 02.- Presupuesto'!A1
B3: Código | C3: Recurso | D3: Unidad | E3: Descripción | F3: Cantidad | G3: Precio Unitario | H3: Total | M3: Mat | N3: MO | O3: SC | P3: Arr
B4: 4.2 | C4: Partida | D4: ='01.- Presupuesto'!F30 -> un | E4: ='01.- Presupuesto'!C30 -> Suministro de materiales y construcción cámaras de filtración y decantación | F4: ='01.- Presupuesto'!G30 -> 1 | G4: =G21 -> 650632.39 | H4: =H21 -> 650632.39 | J4: Cantidad | K4: Costo | M4: =SUMIF(C5:C22,"Material",K5:K22) -> 424713.73 | N4: =SUMIF(C5:C22,"Mano de Obra",K5:K22) -> 144355.56 | O4: =SUMIF(C5:C22,"Subcontrato",K5:K22) -> 37692 | P4: =SUMIF(C5:C22,"Ser&Arr",K5:K22) -> 43871.111 | Q4: =SUM(M4:P4) -> 650632.39
C5: Material | D5: m3 | E5: Hormigón G20(10)20-8 | F5: =((4*1.15*1.15)+(1.3*1.3))*0.15 -> 1.047 | G5: =HormG20 -> 108376.92 | H5: =ROUND(F5*G5,3) -> 113470.63 | J5: =F5*$F$4 -> 1.047 | K5: =H5*$F$4 -> 113470.63
C6: Material | D6: m3 | E6: Carga Incompleta | F6: =6-F5 -> 4.953 | G6: 12000 | H6: =ROUND(F6*G6,3) -> 59436 | J6: =F6*$F$4 -> 4.953 | K6: =H6*$F$4 -> 59436
C7: Material | D7: Kg | E7: Acero A630-420H | F7: =F5*60 -> 62.82 | G7: 900 | H7: =ROUND(F7*G7,3) -> 56538 | J7: =F7*$F$4 -> 62.82 | K7: =H7*$F$4 -> 56538
C8: Material | D8: Kg | E8: Alambre Negro Recocido #18 | F8: =1/30*F7 -> 2.094 | G8: 1630 | H8: =ROUND(F8*G8,3) -> 3413.22 | J8: =F8*$F$4 -> 2.094 | K8: =H8*$F$4 -> 3413.22
C9: Material | D9: un | E9: Tapa diamantada galvanizada | F9: 1 | G9: =129998/1.19 -> 109242.02 | H9: =ROUND(F9*G9,3) -> 109242.02 | J9: =F9*$F$4 -> 1 | K9: =H9*$F$4 -> 109242.02
C10: Material | D10: uni | E10: Pino Verde 2x3" 3,2m | F10: =1/0.48*((4*1.15*1.15)+(1.3*1.3)) -> 14.541667 | G10: 2400 | H10: =ROUND(F10*G10,3) -> 34900 | J10: =F10*$F$4 -> 14.541667 | K10: =H10*$F$4 -> 34900
C11: Material | D11: uni | E11: Terciado Estructural 1,22x2,44m 15 mm | F11: =1.05*1/(1.22*2.44)*((4*1.15*1.15)+(1.3*1.3)) -> 2.4620398 | G11: 16966 | H11: =ROUND(F11*G11,3) -> 41770.967 | J11: =F11*$F$4 -> 2.4620398 | K11: =H11*$F$4 -> 41770.967
C12: Material | D12: kg | E12: Clavos CTE 1 1/2" | F12: =1/4*((4*1.15*1.15)+(1.3*1.3)) -> 1.745 | G12: 1184 | H12: =ROUND(F12*G12,3) -> 2066.08 | J12: =F12*$F$4 -> 1.745 | K12: =H12*$F$4 -> 2066.08
C13: Material | D13: uni | E13: Alambre Negro Recocido #14 25 Kg | F13: =1/72*((4*1.15*1.15)+(1.3*1.3)) -> 0.096944444 | G13: 39990 | H13: =ROUND(F13*G13,3) -> 3876.808 | J13: =F13*$F$4 -> 0.096944444 | K13: =H13*$F$4 -> 3876.808
C14: Mano de Obra | D14: hh | E14: Maestro | F14: 8 | G14: =Maestro -> 7250 | H14: =ROUND(F14*G14,3) -> 58000 | J14: =F14*$F$4 -> 8 | K14: =H14*$F$4 -> 58000
C15: Mano de Obra | D15: hh | E15: Jornal | F15: 16 | G15: =Jornal -> 5397.2222 | H15: =ROUND(F15*G15,3) -> 86355.556 | J15: =F15*$F$4 -> 16 | K15: =H15*$F$4 -> 86355.556
C16: Ser&Arr | D16: % | E16: Desgaste de Herramientas | F16: 0.2 | G16: =SUM(H14:H15) -> 144355.56 | H16: =ROUND(F16*G16,3) -> 28871.111 | J16: =F16*$F$4 -> 0.2 | K16: =H16*$F$4 -> 28871.111
C17: Subcontrato | D17: kg | E17: Enfierrador | F17: =F7 -> 62.82 | G17: =Enf -> 600 | H17: =ROUND(F17*G17,3) -> 37692 | J17: =F17*$F$4 -> 62.82 | K17: =H17*$F$4 -> 37692
C18: Ser&Arr | D18: día | E18: Sonda Vibradora + Motor Bencinero | F18: 1 | G18: =3500+3500 -> 7000 | H18: =ROUND(F18*G18,3) -> 7000 | J18: =F18*$F$4 -> 1 | K18: =H18*$F$4 -> 7000
C19: Ser&Arr | D19: día | E19: Sonda Vibradora + Motor Electrico | F19: 1 | G19: =3500+3500 -> 7000 | H19: =ROUND(F19*G19,3) -> 7000 | J19: =F19*$F$4 -> 1 | K19: =H19*$F$4 -> 7000
C20: Ser&Arr | D20: un | E20: Compresión Probetas Cilindricas | F20: =1/50 -> 0.02 | G20: 50000 | H20: =ROUND(F20*G20,3) -> 1000 | J20: =F20*$F$4 -> 0.02 | K20: =H20*$F$4 -> 1000
E21: Total APU 4.2 | F21: =$F$4 -> 1 | G21: =SUM(H5:H20) -> 650632.39 | H21: =ROUND(F21*G21,3) -> 650632.39 | K21: =SUM(K5:K20) -> 650632.39

Sheet 5.1
B1: 02.- Presupuesto'!A1
B3: Código | C3: Recurso | D3: Unidad | E3: Descripción | F3: Cantidad | G3: Precio Unitario | H3: Total | M3: Mat | N3: MO | O3: SC | P3: Arr
B4: 5.1 | C4: Partida | D4: ='01.- Presupuesto'!F32 -> m | E4: ='01.- Presupuesto'!C32 -> Suministro e instalación cierre perimetral tipo Bulldog | F4: ='01.- Presupuesto'!G32 -> 50 | G4: =G6 -> 30000 | H4: =H6 -> 1500000 | J4: Cantidad | K4: Costo | M4: =SUMIF(C5:C18,"Material",K5:K18) -> 0 | N4: =SUMIF(C5:C18,"Mano de Obra",K5:K18) -> 0 | O4: =SUMIF(C5:C18,"Subcontrato",K5:K18) -> 1500000 | P4: =SUMIF(C5:C18,"Ser&Arr",K5:K18) -> 0 | Q4: =SUM(M4:P4) -> 1500000
C5: Subcontrato | D5: m | E5: Subcontrato Suministro e Instalación Cierro tipo Bulldog | F5: 1 | G5: =SCBulldog -> 30000 | H5: =ROUND(F5*G5,3) -> 30000 | J5: =F5*$F$4 -> 50 | K5: =H5*$F$4 -> 1500000
E6: Total APU 5.1 | F6: =$F$4 -> 50 | G6: =SUM(H5:H5) -> 30000 | H6: =ROUND(F6*G6,3) -> 1500000 | K6: =SUM(K5:K5) -> 1500000

Sheet 5.2
B1: 02.- Presupuesto'!A1
B3: Código | C3: Recurso | D3: Unidad | E3: Descripción | F3: Cantidad | G3: Precio Unitario | H3: Total | M3: Mat | N3: MO | O3: SC | P3: Arr
B4: 5.2 | C4: Partida | D4: ='01.- Presupuesto'!F33 -> m | E4: ='01.- Presupuesto'!C33 -> Suministro e instalación cierre perimetral tipo Acmafor | F4: ='01.- Presupuesto'!G33 -> 280 | G4: =G6 -> 30550 | H4: =H6 -> 8554000 | J4: Cantidad | K4: Costo | M4: =SUMIF(C5:C18,"Material",K5:K18) -> 0 | N4: =SUMIF(C5:C18,"Mano de Obra",K5:K18) -> 0 | O4: =SUMIF(C5:C18,"Subcontrato",K5:K18) -> 8554000 | P4: =SUMIF(C5:C18,"Ser&Arr",K5:K18) -> 0 | Q4: =SUM(M4:P4) -> 8554000
C5: Subcontrato | D5: m | E5: Subcontrato Suministro e Instalación Cierro tipo Acmafor | F5: 1 | G5: =SCAcmafor -> 30550 | H5: =ROUND(F5*G5,3) -> 30550 | J5: =F5*$F$4 -> 280 | K5: =H5*$F$4 -> 8554000
E6: Total APU 5.2 | F6: =$F$4 -> 280 | G6: =SUM(H5:H5) -> 30550 | H6: =ROUND(F6*G6,3) -> 8554000 | K6: =SUM(K5:K5) -> 8554000

Sheet 5.3
B1: 02.- Presupuesto'!A1
B3: Código | C3: Recurso | D3: Unidad | E3: Descripción | F3: Cantidad | G3: Precio Unitario | H3: Total | M3: Mat | N3: MO | O3: SC | P3: Arr
B4: 5.3 | C4: Partida | D4: ='01.- Presupuesto'!F34 -> un | E4: ='01.- Presupuesto'!C34 -> Suministro e instalación portón metálico vehicular 5m | F4: ='01.- Presupuesto'!G34 -> 1 | G4: =G6 -> 1214017 | H4: =H6 -> 1214017 | J4: Cantidad | K4: Costo | M4: =SUMIF(C5:C18,"Material",K5:K18) -> 0 | N4: =SUMIF(C5:C18,"Mano de Obra",K5:K18) -> 0 | O4: =SUMIF(C5:C18,"Subcontrato",K5:K18) -> 1214017 | P4: =SUMIF(C5:C18,"Ser&Arr",K5:K18) -> 0 | Q4: =SUM(M4:P4) -> 1214017
C5: Subcontrato | D5: un | E5: SC Portón Acmafor Vehicular | F5: 1 | G5: 1214017 | H5: =ROUND(F5*G5,3) -> 1214017 | J5: =F5*$F$4 -> 1 | K5: =H5*$F$4 -> 1214017
E6: Total APU 5.3 | F6: =$F$4 -> 1 | G6: =SUM(H5:H5) -> 1214017 | H6: =ROUND(F6*G6,3) -> 1214017 | K6: =SUM(K5:K5) -> 1214017

Sheet 5.4
B1: 02.- Presupuesto'!A1
B3: Código | C3: Recurso | D3: Unidad | E3: Descripción | F3: Cantidad | G3: Precio Unitario | H3: Total | M3: Mat | N3: MO | O3: SC | P3: Arr
B4: 5.4 | C4: Partida | D4: ='01.- Presupuesto'!F35 -> un | E4: ='01.- Presupuesto'!C35 -> Suministro e instalación portón metálico peatonal 1m | F4: ='01.- Presupuesto'!G35 -> 1 | G4: =G6 -> 520466 | H4: =H6 -> 520466 | J4: Cantidad | K4: Costo | M4: =SUMIF(C5:C18,"Material",K5:K18) -> 0 | N4: =SUMIF(C5:C18,"Mano de Obra",K5:K18) -> 0 | O4: =SUMIF(C5:C18,"Subcontrato",K5:K18) -> 520466 | P4: =SUMIF(C5:C18,"Ser&Arr",K5:K18) -> 0 | Q4: =SUM(M4:P4) -> 520466
C5: Subcontrato | D5: Kg | E5: SC Portón Acmafor Peatonal | F5: 1 | G5: 520466 | H5: =ROUND(F5*G5,3) -> 520466 | J5: =F5*$F$4 -> 1 | K5: =H5*$F$4 -> 520466
E6: Total APU 5.4 | F6: =$F$4 -> 1 | G6: =SUM(H5:H5) -> 520466 | H6: =ROUND(F6*G6,3) -> 520466 | K6: =SUM(K5:K5) -> 520466

Sheet 6.1
B1: 02.- Presupuesto'!A1
B3: Código | C3: Recurso | D3: Unidad | E3: Descripción | F3: Cantidad | G3: Precio Unitario | H3: Total | M3: Mat | N3: MO | O3: SC | P3: Arr
B4: 6.1 | C4: Partida | D4: ='01.- Presupuesto'!F39 -> m3 | E4: ='01.- Presupuesto'!C39 -> Suministro e Instalación Hormigón G25(10)20-8 | F4: ='01.- Presupuesto'!G39 -> 36.75 | G4: =G13 -> 141504.27 | H4: =H13 -> 5200281.8 | J4: Cantidad | K4: Costo | M4: =SUMIF(C5:C25,"Material",K5:K25) -> 4568100.2 | N4: =SUMIF(C5:C25,"Mano de Obra",K5:K25) -> 353276.39 | O4: =SUMIF(C5:C25,"Subcontrato",K5:K25) -> 0 | P4: =SUMIF(C5:C25,"Ser&Arr",K5:K25) -> 278905.27 | Q4: =SUM(M4:P4) -> 5200281.8
C5: Material | D5: m3 | E5: Hormigón G25(10)20-8 | F5: 1.1 | G5: =HormG25 -> 111910.95 | H5: =ROUND(F5*G5,3) -> 123102.04 | J5: =F5*$F$4 -> 40.425 | K5: =H5*$F$4 -> 4524000.2
C6: Material | D6: m3 | E6: Carga Incompleta | F6: =0.1 -> 0.1 | G6: 12000 | H6: =ROUND(F6*G6,3) -> 1200 | J6: =F6*$F$4 -> 3.675 | K6: =H6*$F$4 -> 44100
