Workbook

Sheet PP1
A1: Proyecto | C1: Hito1 | D1: Hito2 | E1: Hito3 | F1: Hito4 | G1: Hito5 | H1: Hito6 | I1: Hito7
D2: DIA | E2: Mineros | F2: RCA | G2: ICC | J2: TOTAL | K2: Potencia
A3: Curamachi | B3: EP | C3: 63180 | D3: 31590 | E3: 31590 | F3: 47385 | G3: 31590 | H3: 47385 | I3: 63180 | J3: =SUM(C3:I3) -> 315900 | K3: 10.53 | O3: 30000000 | P3: 12000000
B4: Pagado | C4: =+C3 -> 63180 | D4: 31590 | E4: 31590 | J4: =SUM(C4:I4) -> 126360 | K4: =+J4/J3 -> 0.4
B5: Debe Pagar | J5: =SUM(C5:I5) -> 0 | K5: =+J5/J3 -> 0
A7: Doña Rodriga | B7: EP | C7: =+$J$7*0.2 -> 32160 | D7: =+$J$7*0.1 -> 16080 | E7: =+$J$7*0.1 -> 16080 | F7: =+$J$7*0.15 -> 24120 | G7: =+$J$7*0.1 -> 16080 | H7: =+$J$7*0.15 -> 24120 | I7: =+$J$7*0.2 -> 32160 | J7: =+K7*30000 -> 160800 | K7: 5.36 | O7: 30000000 | P7: 8000000 | Q7: 12000000
B8: Pagado | C8: 16080 | D8: 16080 | E8: 16080 | F8: =+F7 -> 24120 | G8: 16080 | J8: =SUM(C8:I8) -> 88440 | K8: =+J8/J7 -> 0.55 | L8: 104530 | M8: =+L8-J8 -> 16090
B9: Debe Pagar | J9: =SUM(C9:I9) -> 0 | K9: =+J9/J7 -> 0
A11: Agrovisión | B11: EP | C11: =+$J$11*0.2 -> 63180 | D11: =+$J$11*0.1 -> 31590 | E11: =+$J$11*0.1 -> 31590 | F11: =+$J$11*0.15 -> 47385 | G11: =+$J$11*0.1 -> 31590 | H11: =+$J$11*0.15 -> 47385 | I11: =+$J$11*0.2 -> 63180 | J11: =30000*K11 -> 315900 | K11: 10.53 | O11: 30000000 | P11: 12000000
B12: Pagado | C12: 12600 | D12: =+D11 -> 31590 | G12: 33000 | J12: =SUM(C12:I12) -> 77190 | K12: =+J12/J11 -> 0.24434948
B13: Debe Pagar | C13: =+C12-C11 -> -50580 | E13: =+E12-E11 -> -31590 | F13: =+F12-F11 -> -47385 | J13: =SUM(C13:I13) -> -129555 | K13: =+J13/J11 -> -0.41011396
C14: =+C12/J11 -> 0.03988604
A15: La Palma | B15: EP | C15: =+$J$15*0.2 -> 63180 | D15: =+$J$15*0.1 -> 31590 | E15: =+$J$15*0.1 -> 31590 | F15: =+$J$15*0.15 -> 47385 | G15: =+$J$15*0.1 -> 31590 | H15: =+$J$15*0.15 -> 47385 | I15: =+$J$15*0.2 -> 63180 | J15: =30000*K15 -> 315900 | K15: 10.53 | O15: 30000000 | P15: 12000000
B16: Pagado | J16: =SUM(C16:I16) -> 0 | K16: =+J16/J15 -> 0
B17: Debe Pagar | C17: =+C16-C15 -> -63180 | D17: =+D16-D15 -> -31590 | G17: =+G16-G15 -> -31590 | J17: =SUM(C17:I17) -> -126360 | K17: =+J17/J15 -> -0.4
A19: Villa Alegre | B19: EP | C19: =+$J$19*0.2 -> 16050 | D19: =+$J$19*0.1 -> 8025 | E19: =+$J$19*0.1 -> 8025 | F19: =+$J$19*0.15 -> 12037.5 | G19: =+$J$19*0.1 -> 8025 | H19: =+$J$19*0.15 -> 12037.5 | I19: =+$J$19*0.2 -> 16050 | J19: =+(30000+23500)/2*K19 -> 80250 | K19: 3 | L19: =+J19/K19 -> 26750
B20: Pagado | G20: =+G19 -> 8025 | J20: =SUM(C20:I20) -> 8025 | K20: =+J20/J19 -> 0.1 | O20: =+J4+J12 -> 203550
B21: Debe Pagar | C21: =+C20-C19 -> -16050 | D21: =+D20-D19 -> -8025 | E21: =+E20-E19 -> -8025 | F21: =+F20-F19 -> -12037.5 | H21: =+H20-H19 -> -12037.5 | I21: =+I20-I19 -> -16050 | J21: =SUM(C21:I21) -> -72225 | K21: =+J21/J19 -> -0.9 | M21: =+K20-K21 -> 1 | O21: =+J21-+'PP2'!N7 -> -142725
O22: =+O20+O21 -> 60825
A23: Papudo-Quinquimo | B23: EP | C23: =+$J$23*0.2 -> 53125.5 | D23: =+$J$23*0.1 -> 26562.75 | E23: =+$J$23*0.1 -> 26562.75 | F23: =+$J$23*0.15 -> 39844.125 | G23: =+$J$23*0.1 -> 26562.75 | H23: =+$J$23*0.15 -> 39844.125 | I23: =+$J$23*0.2 -> 53125.5 | J23: =+(30000+23500)/2*K23 -> 265627.5 | K23: 9.93
B24: Pagado | J24: =SUM(C24:I24) -> 0 | K24: =+J24/J23 -> 0
B25: Debe Pagar | C25: =+C24-C23 -> -53125.5 | D25: =+D24-D23 -> -26562.75 | E25: =+E24-E23 -> -26562.75 | G25: =+G24-G23 -> -26562.75 | J25: =SUM(C25:I25) -> -132813.75 | K25: =+J25/J23 -> -0.5
A27: El Cuzco | B27: EP | C27: =+$J$27*0.2 -> 58850 | D27: =+$J$27*0.1 -> 29425 | E27: =+$J$27*0.1 -> 29425 | F27: =+$J$27*0.15 -> 44137.5 | G27: =+$J$27*0.1 -> 29425 | H27: =+$J$27*0.15 -> 44137.5 | I27: =+$J$27*0.2 -> 58850 | J27: =+(30000+23500)/2*K27 -> 294250 | K27: 11
B28: Pagado | J28: =SUM(C28:I28) -> 0 | K28: =+J28/J27 -> 0
B29: Debe Pagar | C29: =+C28-C27 -> -58850 | D29: =+D28-D27 -> -29425 | G29: =+G28-G27 -> -29425 | J29: =SUM(C29:I29) -> -117700 | K29: =+J29/J27 -> -0.4
H31: Venta | J31: =+J27+J23+J19+J15+J11+J7+J3 -> 1748627.5 | K31: =+K27+K23+K19+K15+K11+K7+K3 -> 60.88 | L31: =+J31/K31 -> 28722.528
H32: Pagado | I32: =+J32/J31 -> 0.1715717 | J32: =+J28+J24+J20+J16+J12+J8+J4 -> 300015 | K32: =+K28+K24+K20+K16+K12+K8+K4 -> 1.2943495 | N32: =+J32*750 -> 225011250 | O32: =SUM(O3:Q17) -> 176000000 | P32: =+N32-O32 -> 49011250
A33: fecha | H33: debe | I33: =+J33/J31 -> -0.33091882 | J33: =+J29+J25+J21+J17+J13+J9+J5 -> -578653.75 | L33: =+J33*830 -> -4.8028261e+08 | N33: remuneraciones | O33: 24000000 | P33: =+P32-O33 -> 25011250
I34: =+I32-I33 -> 0.50249052
A35: 44370 | B35: 35400 | C35: Agrov}
A36: 44308 | B36: 24120 | C36: RCA dona R
A37: 44272 | B37: 31590 | C37: DIA Agrovision
A38: 44235 | B38: 31590 | C38: min curama
A39: 44235 | B39: 16080 | C39: min dona R
A40: 44257 | B40: 14259000 | C40: acreditaciones | D40: pesos chilenos
A43: 44231 | B43: 31590 | C43: curamachi ito3
A44: 44187 | B44: 15795 | C44: servidumbre curamachi 5%
A45: 44075 | B45: 8000000 | C45: curamachi | D45: pesos chilenos | E45: 78750 | F45: =+E45+B44 -> 94545

Sheet PP2
A1: US/MWp | B1: 23500 | C1: Acreditación | F1: Anticipo 1 | G1: Anticipo 2 | H1: Contrato | I1: ICC | J1: IFC | K1: Concesión Minera | L1: RTB | M1: Conexión
C2: UF | F2: 1.5 | G2: 1.5 | H2: 5 | I2: 5 | J2: 10 | K2: 2 | L2: 55 | M2: 20 | N2: =SUM(F2:M2) -> 100
A3: PROYECTO | B3: POTENCIA | C3: Acreditación | D3: 29509
A4: Los Quillayes | N4: =SUM(F4:M4) -> 0
A5: Calle Larga | N5: =SUM(F5:M5) -> 0
A6: Peñuela | N6: =SUM(F6:M6) -> 0
A7: Doña Rubena | B7: 3 | C7: =+(3949018)/29000 -> 136.17303 | D7: =+C7*$D$3 -> 4018330.1 | E7: 3949018 | F7: =+$B7*$B$1*F$2% -> 1057.5 | G7: =+$B7*$B$1*G$2% -> 1057.5 | H7: =+B7*$B$1*H$2% -> 3525 | I7: =+$B7*$B$1*I$2% -> 3525 | J7: =+$B7*$B$1*J$2% -> 7050 | K7: =+$B7*$B$1*K$2% -> 1410 | L7: =+$B7*$B$1*L$2% -> 38775 | M7: =+$B7*$B$1*M$2% -> 14100 | N7: =SUM(F7:M7) -> 70500
A8: El Rosal | B8: 11 | C8: 90 | D8: =+C8*$D$3 -> 2655810 | E8: 2617830 | N8: =SUM(F8:M8) -> 0
A9: Doña Alicia | B9: 9.14 | C9: 50 | F9: =+$B9*$B$1*F$2% -> 3221.85 | G9: =+$B9*$B$1*G$2% -> 3221.85 | H9: =+B9*$B$1*H$2% -> 10739.5 | I9: =+$B9*$B$1*I$2% -> 10739.5 | J9: =+$B9*$B$1*J$2% -> 21479 | K9: =+$B9*$B$1*K$2% -> 4295.8 | L9: =+$B9*$B$1*L$2% -> 118134.5 | M9: =+$B9*$B$1*M$2% -> 42958 | N9: =SUM(F9:M9) -> 214790
A10: Doña Mago | B10: 10.68 | C10: 90 | N10: =SUM(F10:M10) -> 0
A11: Campanario | B11: 9.46 | C11: 100 | F11: =+$B11*$B$1*F$2% -> 3334.65 | G11: =+$B11*$B$1*G$2% -> 3334.65 | H11: =+B11*$B$1*H$2% -> 11115.5 | I11: =+$B11*$B$1*I$2% -> 11115.5 | J11: =+$B11*$B$1*J$2% -> 22231 | K11: =+$B11*$B$1*K$2% -> 4446.2 | L11: =+$B11*$B$1*L$2% -> 122270.5 | M11: =+$B11*$B$1*M$2% -> 44462 | N11: =SUM(F11:M11) -> 222310
A12: Doña Sonia | B12: 10.68 | C12: 100 | N12: =SUM(F12:M12) -> 0
A13: Doña Petronia | B13: 9.58 | C13: 90 | F13: =+$B13*$B$1*F$2% -> 3376.95 | G13: =+$B13*$B$1*G$2% -> 3376.95 | H13: =+B13*$B$1*H$2% -> 11256.5 | I13: =+$B13*$B$1*I$2% -> 11256.5 | J13: =+$B13*$B$1*J$2% -> 22513 | K13: =+$B13*$B$1*K$2% -> 4502.6 | L13: =+$B13*$B$1*L$2% -> 123821.5 | M13: =+$B13*$B$1*M$2% -> 45026 | N13: =SUM(F13:M13) -> 225130
A14: Doña Ximena | B14: 9.58 | C14: 100 | F14: =+$B14*$B$1*F$2% -> 3376.95 | G14: =+$B14*$B$1*G$2% -> 3376.95 | H14: =+B14*$B$1*H$2% -> 11256.5 | I14: =+$B14*$B$1*I$2% -> 11256.5 | J14: =+$B14*$B$1*J$2% -> 22513 | K14: =+$B14*$B$1*K$2% -> 4502.6 | L14: =+$B14*$B$1*L$2% -> 123821.5 | M14: =+$B14*$B$1*M$2% -> 45026 | N14: =SUM(F14:M14) -> 225130
A15: Santa Maria | B15: 11 | C15: 90 | N15: =SUM(F15:M15) -> 0
A16: Doña Elvira | B16: 10.68 | C16: 90 | D16: =+C16*$D$3 -> 2655810 | E16: 2623410 | N16: =SUM(F16:M16) -> 0 | Q16: |12345e3 | R16: ZX
A17: El Sauce | B17: 11 | C17: 100 | N17: =SUM(F17:M17) -> 0
A18: Maklube | B18: 3 | C18: 50 | F18: =+$B18*$B$1*F$2% -> 1057.5 | G18: =+$B18*$B$1*G$2% -> 1057.5 | H18: =+B18*$B$1*H$2% -> 3525 | I18: =+$B18*$B$1*I$2% -> 3525 | J18: =+$B18*$B$1*J$2% -> 7050 | K18: =+$B18*$B$1*K$2% -> 1410 | L18: =+$B18*$B$1*L$2% -> 38775 | M18: =+$B18*$B$1*M$2% -> 14100 | N18: =SUM(F18:M18) -> 70500
B19: MW
A20: Total Dólar | B20: =SUM(B4:B19) -> 108.8 | C20: =SUM(C4:C19) -> 1086.173 | D20: =SUM(D4:D19) -> 9329950.1 | E20: =SUM(E4:E19) -> 9190258 | F20: =SUM(F4:F19) -> 15425.4 | G20: =SUM(G4:G19) -> 15425.4 | H20: =SUM(H4:H19) -> 51418 | I20: =SUM(I4:I19) -> 51418 | ... N20: =SUM(N4:N19) -> 1028360 | O20: Total
A21: Valor Dólar 19-07-2021 | B21: =+B20*B1 -> 2556800 | C21: =+C20*30000 -> 32585191 | F21: 754.17 | N21: 754.17 | O21: Valor Dólar
A22: Total Pesos | B22: =+B21/B20 -> 23500 | F22: =+F20*F21 -> 11633374 | N22: =+N20*N21 -> 7.7555826e+08 | O22: Total Pesos
B23: =+B21*B24 -> 1.8434528e+09
A24: Valor Dólar | B24: 721 | F24: 716
A25: SUBTOTAL PP1 | B25: =-(+'PP1'!J13+'PP1'!J21+'PP1'!J25) -> 334593.75 | F25: =+-'PP1'!J33 -> 578653.75 | M25: curamachi | N25: =+'PP1'!J4 -> 126360
A26: SUBTOTAL PP2 | B26: =+N20 -> 1028360 | F26: =+N20 -> 1028360 | J26: src | M26: villa alegre | N26: =+'PP1'!J21 -> -72225 | O26: =+N26-N20 -> -1100585
A27: SCR | B27: =+C21-18000000 -> 14585191 | J27: contrato | M27: agrovision | N27: =+'PP1'!J12 -> 77190 | O27: =+N27+N25 -> 203550
A28: TOTAL | B28: =+(B25+B26)*B24+B27 -> 9.9727484e+08 | F28: =+SUM(F25:F27) -> 1607013.8 | N28: =+N25+N27+N26-N20 -> -897035
A30: Siguientes PP1 | B30: =-(+'PP1'!J29+'PP1'!J17)*B24 -> 175967260 | C30: 178785200
B31: =+B28+B30 -> 1.1732421e+09 | C31: 5.9931528e+08 | F31: =+B31-C31 -> 5.7392683e+08
A33: Valor Dólar 29-10-2021 | F33: 830 | N33: =+N20*F33 -> 853538800 | O33: -11746621

Sheet Detalle Valores
E1: HITO 1 | F1: HITO 2 | G1: HITO 3 | H1: HITO 4 | I1: HITO 5 | J1: HITO 6 | K1: HITO 7 | L1: HITO 8
A2: PROYECTO | B2: SOCIEDAD | C2: R.U.T | D2: MWp | E2: 0.015 | F2: 0.015 | G2: 0.05 | H2: 0.05 | I2: 0.02 | J2: 0.1 | K2: 0.55 | L2: 0.2 | M2: 1
A3: Doña Elvira | B3: MVC SOLAR 56 SPA | C3: 76.890.047-7 | D3: 11 | E3: =((+$R$5*D3)*$E$2) -> 3877.5 | F3: =((+$R$5*D3)*$F$2) -> 3877.5 | G3: =((+$R$5*D3)*$G$2) -> 12925 | M3: =SUM(E3:L3) -> 20680 | P3: MOU 1 | Q3: 30.000 usd | R3: 30000
A4: Doña Alicia (expatagua) | B4: MVC SOLAR 20 SPA | C4: 76.864.169-2 | D4: 9.14 | E4: =((+$R$5*D4)*$E$2) -> 3221.85 | F4: =((+$R$5*D4)*$F$2) -> 3221.85 | G4: =((+$R$5*D4)*$G$2) -> 10739.5 | M4: =SUM(E4:L4) -> 17183.2 | P4: MOU transitorio | Q4: 26.750 usd | R4: 26750
A5: Doña Mago (excadena) | B5: MVC SOLAR 32 SPA | C5: 76.869.886-4 | D5: 10.68 | E5: =((+$R$5*D5)*$E$2) -> 3764.7 | M5: =SUM(E5:L5) -> 3764.7 | P5: MOU 2 | Q5: 23.500 usd | R5: 23500
A6: Santa María | B6: MVC SOLAR 49 SPA | C6: 76.880.921-6 | D6: 11 | E6: =((+$R$5*D6)*$E$2) -> 3877.5 | M6: =SUM(E6:L6) -> 3877.5
A7: Doña Petronia | B7: MVC SOLAR 51 SPA | C7: 76.890.025-6 | D7: 9.58 | E7: =((+$R$5*D7)*$E$2) -> 3376.95 | M7: =SUM(E7:L7) -> 3376.95
A8: Campanario | B8: MVC SOLAR 60 SPA | C8: 76.890.054-K | D8: 9.46 | E8: =((+$R$5*D8)*$E$2) -> 3334.65 | M8: =SUM(E8:L8) -> 3334.65
A9: Doña Ximena | B9: MVC SOLAR 35 SPA | C9: 76.869.889-9 | D9: 11 | E9: =((+$R$5*D9)*$E$2) -> 3877.5 | M9: =SUM(E9:L9) -> 3877.5
A10: El Rosal | B10: MVC SOLAR 12 SPA | C10: 76.864.161-7 | D10: 11 | E10: =((+$R$5*D10)*$E$2) -> 3877.5 | F10: =((+$R$5*D10)*$F$2) -> 3877.5 | M10: =SUM(E10:L10) -> 7755
A11: Los Quillayes | B11: MVC SOLAR 19 SPA | C11: 76.864.168-4 | D11: 10.04 | E11: =((+$R$5*D11)*$E$2) -> 3539.1 | F11: =((+$R$5*D11)*$F$2) -> 3539.1 | G11: =((+$R$5*D11)*$G$2) -> 11797 | M11: =SUM(E11:L11) -> 18875.2
A12: Calle Larga | B12: MVC SOLAR 30 SPA | C12: 76.869.884-8 | D12: 8.42 | E12: =((+$R$5*D12)*$E$2) -> 2968.05 | F12: =((+$R$5*D12)*$F$2) -> 2968.05 | G12: =((+$R$5*D12)*$G$2) -> 9893.5 | M12: =SUM(E12:L12) -> 15829.6
A13: Maqlube | B13: MVC SOLAR 41 SPA | C13: 76.880.906-2 | D13: 3 | E13: =((+$R$5*D13)*$E$2) -> 1057.5 | M13: =SUM(E13:L13) -> 1057.5
A14: Doña Rubena | B14: MVC SOLAR 48 SPA | C14: 76.880.918-6 | D14: 3 | E14: =((+$R$5*D14)*$E$2) -> 1057.5 | F14: =((+$R$5*D14)*$F$2) -> 1057.5 | G14: =((+$R$5*D14)*$G$2) -> 3525 | H14: =((+$R$5*D14)*$H$2) -> 3525 | M14: =SUM(E14:L14) -> 9165
E15: =SUM(E3:E14) -> 37830.3 | F15: =SUM(F3:F14) -> 18541.5 | G15: =SUM(G3:G14) -> 48880 | H15: =SUM(H3:H14) -> 3525 | M15: =SUM(M3:M14) -> 108776.8 | N15: 100UF
E16: HITO 1 | F16: HITO 2 | G16: HITO 3 | H16: HITO 4 | I16: HITO 5 | J16: HITO 6 | K16: HITO 7
A17: PROYECTO | B17: SOCIEDAD | C17: R.U.T | D17: MWp | E17: 0.2 | F17: 0.1 | G17: 0.1 | H17: 0.1 | I17: 0.15 | J17: 0.15 | K17: 0.2 | L17: 1
A18: El Cuzco | B18: MVC SOLAR 31 SPA | C18: 76.869.885-6 | D18: 11 | E18: =((+$R$4*D18)*E$17) -> 58850 | F18: =((+$R$4*D18)*$F$17) -> 29425 | G18: =((+$R$4*D18)*$G$17) -> 29425 | H18: =((+$R$4*D18)*$H$17) -> 29425 | I18: =((+$R$4*$D18)*I$17) -> 44137.5 | J18: =((+$R$4*$D18)*J$17) -> 44137.5 | K18: =((+$R$4*$D18)*K$17) -> 58850 | L18: =SUM(E18:K18) -> 294250 | M18: =+SUM(E18:F18,I18) -> 132412.5
A19: Villa Alegre | B19: MVC SOLAR 22 SPA | C19: 76.864.172-2 | D19: 10.53 | E19: =((+$R$4*D19)*$E$17) -> 56335.5 | F19: =((+$R$4*D19)*$F$17) -> 28167.75 | G19: =((+$R$4*D19)*$G$17) -> 28167.75 | H19: =((+$R$4*$D19)*$H$17) -> 28167.75 | I19: =((+$R$4*$D19)*I$17) -> 42251.625 | J19: =((+$R$4*$D19)*J$17) -> 42251.625 | K19: =((+$R$4*$D19)*K$17) -> 56335.5 | L19: =SUM(E19:K19) -> 281677.5 | M19: =+SUM(E19:G19,I19) -> 154922.62
E20: 52110.34 | F20: =+E20-E19 -> -4225.16 | L20: =SUM(L18:L19) -> 575927.5
E21: HITO 1 | F21: HITO 2 | G21: HITO 3 | H21: HITO 4 | I21: HITO 5 | J21: HITO 6 | K21: HITO 7
A22: PROYECTO | B22: SOCIEDAD | C22: R.U.T | D22: MWp | E22: 0.2 | F22: 0.1 | G22: 0.1 | H22: 0.1 | I22: 0.15 | J22: 0.15 | K22: 0.2 | L22: 1
A23: La Palma | B23: MVC SOLAR 5 SPA | C23: 76.864.153-6 | D23: 10.53 | E23: =((+$R$3*$D23)*E$22) -> 63180 | F23: =((+$R$3*$D23)*F$22) -> 31590 | G23: =((+$R$3*$D23)*G$22) -> 31590 | H23: =((+$R$3*$D23)*H$22) -> 31590 | I23: =((+$R$3*$D23)*I$22) -> 47385 | J23: =((+$R$3*$D23)*J$22) -> 47385 | K23: =((+$R$3*$D23)*K$22) -> 63180 | L23: =SUM(E23:K23) -> 315900 | M23: =+SUM(E23:G23,I23) -> 173745
E25: =+E19+E15+F15+F19 -> 140875.05
A26: Curamachi | E26: =+'PP1'!J4 -> 126360
E27: =+E15-E26 -> -88529.7
E28: =+E27+E19+F19+G19 -> 24141.3 | F28: =+E28+M15-E15 -> 95087.8

Sheet Minero
A1: CONCESION | B1: TIPO | C1: TITULAR | D1: ROL NACIONAL | E1: JUZGADO | F1: CAUSA ROL
A2: SAN RAFAEL | B2: Exploración - Constituida | C2: MVC SOLAR 40 SPA | D2: 06304-0106-2 | E2: Juzgado de Letras de Colina | F2: V-523-2018
A3: POLCURA | B3: Exploración - Constituida | C3: MVC SOLAR 60 SPA | D3: 08412-0124-8 | E3: Juzgado de Letras de Yungay | F3: V-244-2019
A4: PEÑASCO REDONDO | B4: Exploración - Constituida | C4: MVC SOLAR 13 SPA | D4: 08413-0170-6 | E4: 1º Juzgado de Letras de Los Angeles | F4: V-174-2019
A5: MACHICURA | B5: Exploración - Pedimento | C5: MVC Solar 24 SpA | D5: 07303-1189-3 | E5: 2º Juzgado de Letras de Linares | F5: V-19-2020
A6: VILLA ALEGRE MVC | B6: Exploración - Pedimento | C6: MVC Solar 22 SpA | D6: 07309-0009-0 | E6: 2º Juzgado de Letras de Linares | F6: V-20-2020
A7: AGROVISION | B7: Exploración - Pedimento | C7: MVC Solar 11 SpA | D7: 16109-0008-5 | E7: Juzgado de Letras de Yungay | F7: V-13-2020
A8: CURAMACHI 2 | B8: Exploración - Pedimento | C8: MVC Solar 24 SpA | D8: 07303-1211-3 | E8: 1º Juzgado de Letras de Linares | F8: V-105-2020
A9: CURAMACHI 1 | B9: Exploración - Pedimento | C9: MVC Solar 24 SpA | D9: 07303-1212-1 | E9: 2º Juzgado de Letras de Linares | F9: V-105-2020
A10: DOÑA RODRIGA 1 | B10: Exploración - Pedimento | C10: MVC Solar 44 SpA | D10: 07201-0088-6 | E10: 3º Juzgado de Letras de Talca | F10: V-99-2020
A11: DOÑA RODRIGA 2 | B11: Exploración - Pedimento | C11: MVC Solar 44 SpA | D11: 07201-0087-8 | E11: 1º Juzgado de Letras de Talca | F11: V-96-2020
A12: VILLA ALEGRE MVC | B12: Exploración - Pedimento | C12: MVC Solar 22 SpA | D12: 07309-0011-2 | E12: 2º Juzgado de Letras de Linares | F12: V-96-2020
A13: DOÑA ELVIRA | B13: Exploración - Pedimento | C13: MVC Solar 56 SpA | E13: 2º Juzgado Civil de Chillán | F13: V-23-2021
A14: PAPUDO QUINQUIMO | B14: Exploración - Pedimento | C14: MVC Solar 46 SpA | E14: Juzgado de Letras de La Ligua | F14: V-34-2021
A15: LA PALMA | B15: Exploración - Pedimento | C15: MVC Solar 5 SpA | E15: Juzgado de Letras de Yungay | F15: V-7-2021
A16: CALLE LARGA | B16: Exploración - Pedimento | C16: MVC Solar 30 SpA | E16: Juzgado de Letras de San Javier | F16: V-14-2021
A17: LOS QUILLAYES | B17: Exploración - Pedimento | C17: MVC Solar 19 SpA | E17: 1º Juzgado de Letras de Talca | F17: V-42-2021
A18: DOÑA RUBENA | B18: Exploración - Pedimento | C18: MVC Solar 48 SpA | E18: Juzgado de Letras de Colina | F18: V-90-2021
A21: 44419
A22: CONCESIÓN | B22: TIPO CONCESIÓN | C22: ESTADO | D22: ROL NAC. | E22: TITULAR | F22: CAUSA ROL | G22: JUZGADO
A23: AGROVISION | B23: Exploración | C23: Constituida | D23: 16109-0008-5 | E23: MVC Solar 11 SpA | F23: V-13-2020 | G23: Juzgado de Letras de Yungay
A24: CURAMACHI 1 | B24: Exploración | C24: Constituida | D24: 07303-1212-1 | E24: MVC Solar 24 SpA | F24: V-105-2020 | G24: 2º Juzgado de Letras de Linares
A25: DOÑA RODRIGA 2 | B25: Exploración | C25: Constituida | D25: 07201-0087-8 | E25: MVC Solar 44 SpA | F25: V-96-2020 | G25: 1º Juzgado de Letras de Talca
A26: PEÑASCO REDONDO | B26: Exploración | C26: Constituida | D26: 08413-0170-6 | E26: MVC SOLAR 13 SPA | F26: V-174-2019 | G26: 1º Juzgado de Letras de Los Angeles
A27: POLCURA | B27: Exploración | C27: Constituida | D27: 08412-0124-8 | E27: MVC SOLAR 60 SPA | F27: V-244-2019 | G27: Juzgado de Letras de Yungay
A28: SAN RAFAEL | B28: Exploración | C28: Constituida | D28: 06304-0106-2 | E28: MVC SOLAR 40 SPA | F28: V-523-2018 | G28: Juzgado de Letras de Colina
A29: VILLA ALEGRE MVC | B29: Exploración | C29: Constituida | D29: 07309-0011-2 | E29: MVC Solar 22 SpA | F29: V-96-2020 | G29: Juzgado de Letras de San Javier
A30: CALLE LARGA | B30: Exploración | C30: En tramite - Pedim. | D30: 07310-0541-9 | E30: MVC Solar 30 SpA | F30: V-14-2021 | G30: Juzgado de Letras de San Javier
A31: CURAMACHI 2 | B31: Exploración | C31: En tramite - Pedim. | D31: 07303-1211-3 | E31: MVC Solar 24 SpA | F31: V-105-2020 | G31: 1º Juzgado de Letras de Linares
A32: DOÑA ELVIRA | B32: Exploración | C32: En tramite - Pedim. | D32: 16101-0019-4 | E32: MVC Solar 56 SpA | F32: V-23-2021 | G32: 2º Juzgado Civil de Chillán
A33: DOÑA RODRIGA 1 | B33: Exploración | C33: En tramite - Pedim. | D33: 07201-0088-6 | E33: MVC Solar 44 SpA | F33: V-99-2020 | G33: 3º Juzgado de Letras de Talca
A34: DOÑA RUBENA | B34: Exploración | C34: En tramite - Pedim. | D34: 13203-0648-1 | E34: MVC Solar 48 SpA | F34: V-90-2021 | G34: Juzgado de Letras de Colina
A35: LA PALMA | B35: Exploración | C35: En tramite - Pedim. | E35: MVC Solar 5 SpA | F35: V-7-2021 | G35: Juzgado de Letras de Yungay
A36: LOS QUILLAYES | B36: Exploración | C36: En tramite - Pedim. | D36: 07203-0076-1 | E36: MVC Solar 19 SpA | F36: V-42-2021 | G36: 1º Juzgado de Letras de Talca
A37: MACHICURA | B37: Exploración | C37: En tramite - Pedim. | D37: 07303-1189-3 | E37: MVC Solar 24 SpA | F37: V-19-2020 | G37: 2º Juzgado de Letras de Linares
A38: PAPUDO QUINQUIMO | B38: Exploración | C38: En tramite - Pedim. | D38: 05201-1231-6 | E38: MVC Solar 46 SpA | F38: V-34-2021 | G38: Juzgado de Letras de La Ligua
A39: VILLA ALEGRE MVC | B39: Exploración | C39: En tramite - Pedim. | D39: 07309-0009-0 | E39: MVC Solar 22 SpA | F39: V-20-2020 | G39: 2º Juzgado de Letras de Linares
A42: 44509
A43: CONCESIÓN | B43: TIPO CONCESIÓN | C43: ESTADO | D43: ROL NAC. | E43: TITULAR | F43: CAUSA ROL | G43: JUZGADO
A44: AGROVISION | B44: Exploración | C44: Constituida | D44: 16109-0008-5 | E44: MVC Solar 11 SpA | F44: V-13-2020 | G44: Juzgado de Letras de Yungay
...

Sheet Hoja2
A1: PROYECTO | B1: UF
A2: Los Quillayes | B2: 90
A3: Calle Larga | B3: 90
A4: Doña Rubena | B4: =+(3949018)/29000 -> 136.17303
A5: Monte Verde | B5: =+(738810)/29000+90 -> 115.47621
A6: El Rosal | B6: 90
A7: Doña Elvira | B7: 90
A8: Total a Pagar | B8: =SUM(B2:B7) -> 611.64924

Sheet DIA
A5: ORG | B5: Los Quillayes | C5: Campanario | D5: Villa Alegre | G5: Curamachi Rev02 | H5: Curamachi | I5: Agrovisión | J5: Calle Larga | K5: Doña Alicia | L5: Doña Petronia | M5: Doña Elvira | N5: Papudo | O5: Doña Ximena | P5: El Rosal | S5: Santa Maria | T5: Doña Mago | U5: El Cuzco | V5: La Palma | W5: El Sauce | X5: Doña Sonia | Y5: Peñasco Redondo
A6: CMN | I6: antes sin nada
A7: SAG | D7: CAV
A8: DGA
A9: CONAF | L9: NP | S9: NP | W9: NP
A10: SERNAGEOMIN | H10: NP
A11: DOH | C11: NP | I11: NP | S11: NP
A12: IMUNICIPALIDAD
A13: SubPescaAgri | C13: NP | G13: NP | H13: NP | I13: NP | N13: NP | O13: NP | V13: NP | X13: NP
A14: CONADI
A15: Turismo
A16: DIREC VIALIDAD
A17: CorpNacDesar Indígena
A18: SEC | D18: NP | G18: NP | H18: NP | J18: NP | L18: NP | N18: NP | S18: NP | V18: NP
A19: GORE
A20: DOH | I20: NP
A21: SSSanitarios | C21: NP | I21: NP | N21: NP | S21: NP
A22: SALUD
A23: MEDIO AMBIENTE
A24: MOP
A25: AGRICULTURA
A26: Desarrollo Social y Flia
A27: VIVIENDA
A28: ENERGIA
A29: BIENES NACIONALES | K29: NP | N29: NP
A30: TRANS Y TELE
A32: PAC | C32: si | G32: 17 | I32: 2 | N32: PAC | O32: PAC
A33: envio pac | G33: 44599
A34: Ingreso DIA | D34: 44335 | G34: 44518 | H34: 44518 | L34: 44323 | O34: 44392 | T34: 44400
A35: ICSARA | G35: 44926 | O35: 44442 | T35: 44414 | W35: 44376
A36: Adenda | B36: 44444 | C36: 44412 | G36: 44680 | J36: 44428 | L36: 44436 | M36: 44414 | S36: 44412 | U36: 44417 | W36: 44405 | X36: 44414
A37: resp adenda | C37: 44498 | D37: 44454 | J37: 44445 | K37: 44533 | M37: =+M36+30 -> 44444 | N37: 44449 | S37: 44454 | T37: 44491
A38: 2da | B38: 44469 | D38: 44467 | I38: 44638 | J38: 44459 | K38: 44638 | M38: 44473 | O38: 44620 | P38: 44638 | S38: 44512
A40: 44462 | U40: A espera del aviso radial
B41: conte 30-9 | D41: cont 28-9 | J41: contes 20-9 | M41: Contestado 04/10
J42: va mal con 4 obs | K42: 5 meses para responder icsara
A43: R3spuesta Adenda 2 | B43: 44540 | D43: 44557 | J43: 44545 | M43: 44624 | T43: 44559 | U43: 44550
J44: 44558
B46: OK | J46: Cerrado con dos obs. Por uso de suelo y PAS | L46: 14-2 se sube respuesta comité | N46: Se aplazó 60+30 desde el 03-02 | O46: Lo Mataron, no ingresaron respuesta a Fin de Enero

Sheet Hoja1
A1: seba | B1: marcela | C1: lista las puertas | D1: 44392
C2: baño ok
A4: luca | B4: calicata | C4: sello fundaciones | D4: Sept
B5: inst faena
A8: raul | B8: calicata | C8: sello fundaciones | D8: Sept

Sheet Hoja3
A1: CONCESIÓN | B1: TIPO CONCESIÓN | C1: ESTADO | D1: ROL NAC. | E1: TITULAR | F1: CAUSA ROL | G1: JUZGADO
A2: AGROVISION | B2: Exploración | C2: Constituida | D2: 16109-0008-5 | E2: MVC Solar 11 SpA | F2: V-13-2020 | G2: Juzgado de Letras de Yungay
A3: CALLE LARGA | B3: Exploración | C3: En tramite - Pedim. | E3: MVC Solar 30 SpA | F3: V-14-2021 | G3: Juzgado de Letras de San Javier
A4: CURAMACHI 1 | B4: Exploración | C4: Constituida | D4: 07303-1212-1 | E4: MVC Solar 24 SpA | F4: V-105-2020 | G4: 2º Juzgado de Letras de Linares
A5: CURAMACHI 2 | B5: Exploración | C5: En tramite - Pedim. | D5: 07303-1211-3 | E5: MVC Solar 24 SpA | F5: V-105-2020 | G5: 1º Juzgado de Letras de Linares
A6: DOÑA ELVIRA | B6: Exploración | C6: En tramite - Pedim. | D6: 16101-0019-4 | E6: MVC Solar 56 SpA | F6: V-23-2021 | G6: 2º Juzgado Civil de Chillán
A7: DOÑA RODRIGA 1 | B7: Exploración | C7: En tramite - Pedim. | D7: 07201-0088-6 | E7: MVC Solar 44 SpA | F7: V-99-2020 | G7: 3º Juzgado de Letras de Talca
A8: DOÑA RODRIGA 2 | B8: Exploración | C8: En tramite - Pedim. | D8: 07201-0087-8 | E8: MVC Solar 44 SpA | F8: V-96-2020 | G8: 1º Juzgado de Letras de Talca
A9: DOÑA RUBENA | B9: Exploración | C9: En tramite - Pedim. | E9: MVC Solar 48 SpA | F9: V-90-2021 | G9: Juzgado de Letras de Colina
A10: LA PALMA | B10: Exploración | C10: En tramite - Pedim. | E10: MVC Solar 5 SpA | F10: V-7-2021 | G10: Juzgado de Letras de Yungay
A11: LOS QUILLAYES | B11: Exploración | C11: En tramite - Pedim. | E11: MVC Solar 19 SpA | F11: V-42-2021 | G11: 1º Juzgado de Letras de Talca
A12: MACHICURA | B12: Exploración | C12: En tramite - Pedim. | D12: 07303-1189-3 | E12: MVC Solar 24 SpA | F12: V-19-2020 | G12: 2º Juzgado de Letras de Linares
A13: PAPUDO QUINQUIMO | B13: Exploración | C13: En tramite - Pedim. | D13: 05201-1231-6 | E13: MVC Solar 46 SpA | F13: V-34-2021 | G13: Juzgado de Letras de La Ligua
A14: PEÑASCO REDONDO | B14: Exploración | C14: Constituida | D14: 08413-0170-6 | E14: MVC SOLAR 13 SPA | F14: V-174-2019 | G14: 1º Juzgado de Letras de Los Angeles
A15: POLCURA | B15: Exploración | C15: Constituida | D15: 08412-0124-8 | E15: MVC SOLAR 60 SPA | F15: V-244-2019 | G15: Juzgado de Letras de Yungay
A16: SAN RAFAEL | B16: Exploración | C16: Constituida | D16: 06304-0106-2 | E16: MVC SOLAR 40 SPA | F16: V-523-2018 | G16: Juzgado de Letras de Colina
A17: VILLA ALEGRE MVC | B17: Exploración | C17: Constituida | D17: 07309-0011-2 | E17: MVC Solar 22 SpA | F17: V-96-2020 | G17: Juzgado de Letras de San Javier
A18: VILLA ALEGRE MVC | B18: Exploración | C18: En tramite - Pedim. | D18: 07309-0009-0 | E18: MVC Solar 22 SpA | F18: V-20-2020 | G18: 2º Juzgado de Letras de Linares
A24: «

Sheet Hoja4
B2: 1.5
A3: PROYECTO | B3: Anticipo 1
A4: Los Quillayes | B4: 3539.1
A5: Calle Larga | B5: 2968.05
A6: Doña Rubena | B6: 1057.5
A7: El Rosal | B7: 3877.5
A8: Doña Alicia | B8: 3221.85
A9: Doña Mago | B9: 3764.7
A10: Campanario | B10: 3334.65
A11: Doña Petronia | B11: 3376.95
A12: Doña Ximena | B12: 3877.5
A13: Santa Maria | B13: 3877.5
A14: Doña Elvira | B14: 3764.7
A15: Maklube | B15: 1057.5
A17: Total Dólar | B17: =SUM(B4:B15) -> 37717.5

Sheet Hoja5

Sheet Hoja6
A1: ORG | B1: Los Quillayes | C1: Calle Larga
A2: DGA | F2: OBS
A3: CONAF | F3: OK
A4: SAG | F4: OK al principio
A5: SERNAGEOMIN | F5: OBS al principio
A6: DOH
A7: IMUNICIPALIDAD
A8: SubPescaAgri
A9: CONADI
A10: Turismo
A11: DIREC VIALIDAD
A12: CMN
A13: SALUD
A14: ENERGIA
A15: VIVIENDA
A16: MEDIO AMBIENTE
A17: MOP
... A20: Desarrollo Social y Flia
